Workbook

Sheet A
A1: City Government of Panabo
A2: CONSOLIDATED DETAILED STATEMENT OF FINANCIAL POSITION (BY FUND)
A3: As at December 31, 2021
A4: (With Comparative Figures for CY 2020)
A5: (In Philippine Peso)
A7: PARTICULARS | F7: 2021 | K7: 2020 | P7: 2019
F8: TOTAL | G8: GF | H8: SEF | I8: TF | K8: TOTAL | L8: GF | M8: SEF | N8: TF | P8: TOTAL | Q8: GF | R8: SEF | S8: TF
A9: ASSETS
A10: CURRENT ASSETS
B11: CASH AND CASH EQUIVALENTS
C12: Cash on Hand
D13: Cash Local Treasury | F13: =G13+H13+I13 -> 2681394.5 | G13: 1489852.3 | H13: 1191542.2 | I13: 0 | K13: =L13+M13+N13 -> 4330941 | L13: 2950687.1 | M13: 1376653.9 | N13: 3600 | P13: =Q13+R13+S13 -> 18646663 | Q13: 11921215 | R13: 5695870.5 | S13: 1029577
D14: Petty Cash | F14: =G14+H14+I14 -> 0 | K14: =L14+M14+N14 -> 0 | P14: =Q14+R14+S14 -> 0
C15: Cash in Bank-Local Currency
D16: Cash in Bank -Local Currency, Current Account | F16: =G16+H16+I16 -> 1.3523999e+09 | G16: 7.7697196e+08 | H16: 80064146 | I16: 4.9536376e+08 | K16: =L16+M16+N16 -> 1.1498582e+09 | L16: 9.0900227e+08 | M16: 77943922 | N16: 1.6291201e+08 | P16: =Q16+R16+S16 -> 8.4300502e+08 | Q16: 7.1307069e+08 | R16: 50529243 | S16: 79405087
D17: Cash in Bank -Local Currency, Savings Account | F17: =G17+H17+I17 -> 0 | K17: =L17+M17+N17 -> 0 | P17: =Q17+R17+S17 -> 0
C18: Cash in Bank- Foreign Currency
D19: Cash in Bank - Foreign Currency, Current Account | F19: =G19+H19+I19 -> 0 | K19: =L19+M19+N19 -> 0 | P19: =Q19+R19+S19 -> 0
D20: Cash in Bank - Foreign Currency, Savings Account | F20: =G20+H20+I20 -> 0 | K20: =L20+M20+N20 -> 0 | P20: =Q20+R20+S20 -> 0
C21: Investments in Time Deposits (90 days)
D22: Cash in Bank - Local Currency, Time Deposits | F22: =G22+H22+I22 -> 0 | G22: 0 | H22: 0 | I22: 0 | K22: =L22+M22+N22 -> 0 | L22: 0 | M22: 0 | N22: 0 | P22: =Q22+R22+S22 -> 57813241 | Q22: 57813241 | R22: 0 | S22: 0
D23: Cash in Bank - Foreign Currency, Time Deposits | F23: =G23+H23+I23 -> 0 | K23: =L23+M23+N23 -> 0 | P23: =Q23+R23+S23 -> 0
D24: Treasury Bills | F24: =G24+H24+I24 -> 0 | K24: =L24+M24+N24 -> 0 | P24: =Q24+R24+S24 -> 0
C25: Total Cash and Cash Equivalent | F25: =SUM(F13:F24) -> 1.3550813e+09 | G25: =SUM(G13:G24) -> 7.7846181e+08 | H25: =SUM(H13:H24) -> 81255688 | I25: =SUM(I13:I24) -> 4.9536376e+08 | K25: =SUM(K13:K24) -> 1.1541891e+09 | L25: =SUM(L13:L24) -> 9.1195295e+08 | M25: =SUM(M13:M24) -> 79320576 | N25: =SUM(N13:N24) -> 1.6291561e+08 | P25: =SUM(P13:P24) -> 9.1946492e+08 | Q25: =SUM(Q13:Q24) -> 7.8280515e+08 | R25: =SUM(R13:R24) -> 56225113 | S25: =SUM(S13:S24) -> 80434664 | U25: =+K25-P25 -> 2.3472422e+08
B26: INVESTMENTS
C27: Investments in Time Deposits ( 91 days to 1 year)
D28: Cash in Bank - Local Currency, Time Deposits | F28: =G28+H28+I28 -> 0 | K28: =L28+M28+N28 -> 0 | P28: =Q28+R28+S28 -> 0
D29: Cash in Bank - Foreign Currency, Time Deposits | F29: =G29+H29+I29 -> 0 | K29: =L29+M29+N29 -> 0 | P29: =Q29+R29+S29 -> 0
D30: Treasury Bills | F30: =G30+H30+I30 -> 0 | K30: =L30+M30+N30 -> 0 | P30: =Q30+R30+S30 -> 0
C31: Financial Assets at Fair Value through Surplus or Deficit
D32: Financial Assets Held for Trading | F32: =G32+H32+I32 -> 0 | K32: =L32+M32+N32 -> 0 | P32: =Q32+R32+S32 -> 0
D33: Financial Assets Designated at Fair Value through Surplus or Deficit | F33: =G33+H33+I33 -> 0 | K33: =L33+M33+N33 -> 0 | P33: =Q33+R33+S33 -> 0
C34: Financial Assets - Held to Maturity
D35: Investment in Treasury Bills - Local | F35: =G35+H35+I35 -> 0 | K35: =L35+M35+N35 -> 0 | P35: =Q35+R35+S35 -> 0
D36: Allowance for Impairment - Investment in Treasury Bills - Local | F36: =G36+H36+I36 -> 0 | K36: =L36+M36+N36 -> 0 | P36: =Q36+R36+S36 -> 0
D37: Investment in Bonds - Local | F37: =G37+H37+I37 -> 0 | K37: =L37+M37+N37 -> 0 | P37: =Q37+R37+S37 -> 0
D38: Allowance for Impairment - Investment in Bonds - Local | F38: =G38+H38+I38 -> 0 | K38: =L38+M38+N38 -> 0 | P38: =Q38+R38+S38 -> 0
C39: Financial Assets - Available for Sale
D40: Investments in Stocks | F40: =G40+H40+I40 -> 0 | K40: =L40+M40+N40 -> 0 | P40: =Q40+R40+S40 -> 0
D41: Investments in Bonds | F41: =G41+H41+I41 -> 0 | K41: =L41+M41+N41 -> 0 | P41: =Q41+R41+S41 -> 0
...

Sheet B
A1: City Government of Panabo
A2: CONSOLIDATED DETAILED STATEMENT OF FINANCIAL PERFORMANCE (BY FUND)
A3: For the Year Ended December 31, 2021
A4: (With Comparative figures in 2020)
A5: (In Philippine Peso)
A7: PARTICULARS | F7: 2021 | K7: 2020 | P7: 2019
F8: TOTAL | G8: GF | H8: SEF | I8: TF | K8: TOTAL | L8: GF | M8: SEF | N8: TF | P8: TOTAL | Q8: GF | R8: SEF | S8: TF
A10: REVENUE
B11: TAX REVENUE
C12: Tax Revenue - Individual and Corporation
D13: Professional Tax | F13: =SUM(G13:I13) -> 245025 | G13: 245025 | H13: 0 | I13: 0 | K13: =SUM(L13:N13) -> 277456.5 | L13: 277456.5 | M13: 0 | N13: 0 | P13: =SUM(Q13:S13) -> 255920 | Q13: 255920 | R13: 0 | S13: 0
D14: Community Tax | F14: =SUM(G14:I14) -> 5212532.6 | G14: 5212532.6 | H14: 0 | I14: 0 | K14: =SUM(L14:N14) -> 5438433.1 | L14: 5438433.1 | M14: 0 | N14: 0 | P14: =SUM(Q14:S14) -> 4715687.4 | Q14: 4715687.4 | R14: 0 | S14: 0
C15: Tax Revenue - Property
D16: Real Property Tax- Basic | F16: =SUM(G16:I16) -> 44414879 | G16: 44414879 | H16: 0 | I16: 0 | K16: =SUM(L16:N16) -> 40528682 | L16: 40528682 | M16: 0 | N16: 0 | P16: =SUM(Q16:S16) -> 40306697 | Q16: 40306697 | R16: 0 | S16: 0
D17: Discount on Real Property Tax- Basic | F17: =SUM(G17:I17) -> -3152274.1 | G17: -3152274.1 | H17: 0 | I17: 0 | K17: =SUM(L17:N17) -> -2664119.4 | L17: -2664119.4 | M17: 0 | N17: 0 | P17: =SUM(Q17:S17) -> -2712968.4 | Q17: -2712968.4 | R17: 0 | S17: 0
D18: Special Education Tax | F18: =SUM(G18:I18) -> 63354365 | G18: 0 | H18: 63354365 | I18: 0 | K18: =SUM(L18:N18) -> 59453586 | L18: 0 | M18: 59453586 | N18: 0 | P18: =SUM(Q18:S18) -> 57578153 | Q18: 0 | R18: 57578153 | S18: 0
D19: Discount on Special Education Tax | F19: =SUM(G19:I19) -> -4591616 | G19: 0 | H19: -4591616 | I19: 0 | K19: =SUM(L19:N19) -> -3930162.8 | L19: 0 | M19: -3930162.8 | N19: 0 | P19: =SUM(Q19:S19) -> -3875729.8 | Q19: 0 | R19: -3875729.8 | S19: 0
D20: Special Levy on Idle Lands | F20: =SUM(G20:I20) -> 0 | K20: =SUM(L20:N20) -> 1995681.8 | L20: 1995681.8 | P20: =SUM(Q20:S20) -> 0
D21: Special Levy on Lands Benefited by Public Works Projects | F21: =SUM(G21:I21) -> 0 | K21: =SUM(L21:N21) -> 0 | P21: =SUM(Q21:S21) -> 0
D22: Real Property Transfer Tax | F22: =SUM(G22:I22) -> 4688711.5 | G22: 4688711.5 | H22: 0 | I22: 0 | K22: =SUM(L22:N22) -> 0 | L22: 0 | M22: 0 | N22: 0 | P22: =SUM(Q22:S22) -> 6165311.5 | Q22: 6165311.5
C23: Tax Revenue - Goods and Services
D24: Business Tax | F24: =SUM(G24:I24) -> 1.5381983e+08 | G24: 1.5381983e+08 | H24: 0 | I24: 0 | K24: =SUM(L24:N24) -> 1.6547119e+08 | L24: 1.6547119e+08 | M24: 0 | N24: 0 | P24: =SUM(Q24:S24) -> 1.5171474e+08 | Q24: 1.5171474e+08 | R24: 0 | S24: 0
D25: Tax on Sand, Gravel and Other Quarry Products | F25: =SUM(G25:I25) -> 3418089.8 | G25: 3418089.8 | H25: 0 | I25: 0 | K25: =SUM(L25:N25) -> 2418823 | L25: 2418823 | M25: 0 | N25: 0 | P25: =SUM(Q25:S25) -> 941796.89 | Q25: 941796.89 | R25: 0 | S25: 0
D26: Tax on Delivery Trucks and Vans | F26: =SUM(G26:I26) -> 2460206.2 | G26: 2460206.2 | H26: 0 | I26: 0 | K26: =SUM(L26:N26) -> 2323700.5 | L26: 2323700.5 | M26: 0 | N26: 0 | P26: =SUM(Q26:S26) -> 2384417.2 | Q26: 2384417.2 | R26: 0 | S26: 0
D27: Amusement Tax | F27: =SUM(G27:I27) -> 441866.53 | G27: 441866.53 | H27: 0 | I27: 0 | K27: =SUM(L27:N27) -> 390725 | L27: 390725 | M27: 0 | N27: 0 | P27: =SUM(Q27:S27) -> 10111883 | Q27: 10111883 | R27: 0 | S27: 0
D28: Franchise Tax | F28: =SUM(G28:I28) -> 12152951 | G28: 12152951 | H28: 0 | I28: 0 | K28: =SUM(L28:N28) -> 3650086.4 | L28: 3650086.4 | P28: =SUM(Q28:S28) -> 592.88 | Q28: 592.88 | R28: 0 | S28: 0
D29: Printing and Publication Tax | F29: =SUM(G29:I29) -> 0 | K29: =SUM(L29:N29) -> 0 | P29: =SUM(Q29:S29) -> 0
C30: Tax Revenue - Others
D31: Other Taxes | F31: =SUM(G31:I31) -> 0 | K31: =SUM(L31:N31) -> 0 | P31: =SUM(Q31:S31) -> 0 | Q31: 0 | R31: 0 | S31: 0
C32: Tax Revenue - Fines and Penalties
D33: Tax Revenue - Fines and Penalties - Taxes on Individual and Corporation | F33: =SUM(G33:I33) -> 4961851.9 | G33: 4961851.9 | H33: 0 | I33: 0 | K33: =SUM(L33:N33) -> 4105374 | L33: 4105374 | M33: 0 | N33: 0 | P33: =SUM(Q33:S33) -> 5080638.7 | Q33: 5080638.7 | R33: 0 | S33: 0
D34: Tax Revenue - Fines and Penalties - Property Taxes | F34: =SUM(G34:I34) -> 7284253.1 | G34: 3017330 | H34: 4266923.1 | I34: 0 | K34: =SUM(L34:N34) -> 6397034.8 | L34: 2633779.1 | M34: 3763255.7 | N34: 0 | P34: =SUM(Q34:S34) -> 7657814.1 | Q34: 3152732.3 | R34: 4505081.8 | S34: 0
D35: Tax Revenue - Fines and Penalties - Taxes on Goods and Services | F35: =SUM(G35:I35) -> 0 | K35: =SUM(L35:N35) -> 0 | P35: =SUM(Q35:S35) -> 0
D36: Tax Revenue - Fines and Penalties - Other Taxes | F36: =SUM(G36:I36) -> 0 | K36: =SUM(L36:N36) -> 0 | P36: =SUM(Q36:S36) -> 0
C37: Total Tax Revenue | F37: =SUM(F12:F36) -> 2.9471068e+08 | G37: =SUM(G12:G36) -> 2.31681e+08 | H37: =SUM(H12:H36) -> 63029672 | I37: =SUM(I12:I36) -> 0 | K37: =SUM(K12:K36) -> 2.8585649e+08 | L37: =SUM(L12:L36) -> 2.2656981e+08 | M37: =SUM(M12:M36) -> 59286679 | N37: =SUM(N12:N36) -> 0 | P37: =SUM(P12:P36) -> 2.8032495e+08 | Q37: 2.2211745e+08 | R37: 58207505 | S37: 0 | U37: =+K37-P37 -> 5531540.3
B38: SHARE FROM NATIONAL TAXES
C39: Share from Internal Revenue Collections (IRA) | F39: =SUM(G39:I39) -> 889216030 | G39: 889216030 | H39: 0 | I39: 0 | K39: =SUM(L39:N39) -> 829672451 | L39: 829672451 | M39: 0 | N39: 0 | P39: =SUM(Q39:S39) -> 7.3921276e+08 | Q39: 7.3921276e+08 | R39: 0 | S39: 0 | U39: =+K39-P39 -> 90459686
B40: OTHER SHARE FROM NATIONAL TAXES
C41: Share from Expanded Value Added Tax | F41: =SUM(G41:I41) -> 0 | K41: =SUM(L41:N41) -> 0 | P41: =SUM(Q41:S41) -> 0
C43: Share from National Wealth | F43: =SUM(G43:I43) -> 0 | G43: 0 | I43: 0 | K43: =SUM(L43:N43) -> 131344.5 | L43: 131344.5 | M43: 0 | N43: 0 | P43: =SUM(Q43:S43) -> 0 | Q43: 0 | R43: 0 | S43: 0
...

Sheet C
A1: City Government of Panabo
A2: CONSOLIDATED DETAILED STATEMENT OF CHANGES IN NET ASSETS/EQUITY (BY FUND)
A3: For the Year Ended December 31, 2021
A4: (With Comparative figures in 2020)
A5: (In Philippine Peso)
A8: PARTICULARS | E8: 2021 | J8: 2020 | O8: 2019
E9: TOTAL | F9: GF | G9: SEF | H9: TF | J9: TOTAL | K9: GF | L9: SEF | M9: TF | O9: TOTAL | P9: GF | Q9: SEF | R9: TF
A10: NET ASSETS/EQUITY
B11: Balance at January 1 | E11: =F11+G11+H11 -> 2.9496322e+09 | F11: =K27 -> 2.616398e+09 | G11: =L27 -> 2.9652596e+08 | H11: =M27 -> 36708289 | J11: =K11+L11+M11 -> 2.7744008e+09 | K11: =+P27 -> 2.4647606e+09 | L11: =+Q27 -> 2.7664128e+08 | M11: =+R27 -> 32998941 | O11: =P11+Q11+R11 -> 2.3950854e+09 | P11: 2.109949e+09 | Q11: 2.4300416e+08 | R11: 42132187
B12: Adjustment to Government Equity, beginning | E12: =F12+G12+H12 -> 0 | J12: =K12+L12+M12 -> 0 | O12: 0 | P12: 0 | Q12: 0 | R12: 0
C13: Add (Deduct) | Q13: 0 | R13: 0
D14: Change in Accounting Policy | E14: =F14+G14+H14 -> 0 | F14: 0 | G14: 0 | H14: 0 | J14: =K14+L14+M14 -> 0 | K14: 0 | L14: 0 | M14: 0 | O14: =P14+Q14+R14 -> 0 | P14: 0 | Q14: 0 | R14: 0
D15: Prior Period Errors | E15: =F15+G15+H15 -> -3.4565567e+08 | F15: -1.6363516e+08 | G15: -1.8061434e+08 | H15: -1406171.7 | J15: =K15+L15+M15 -> -1.9122355e+08 | K15: -1.7841096e+08 | L15: -11650871 | M15: -1161725.2 | O15: =P15+Q15+R15 -> -10194319 | P15: -13667844 | Q15: 3680350.3 | R15: -206825.25
B16: Restated Balance | E16: =SUM(E11:E15) -> 2.6039765e+09 | F16: =SUM(F11:F15) -> 2.4527628e+09 | G16: =SUM(G11:G15) -> 1.1591162e+08 | H16: =SUM(H11:H15) -> 35302117 | J16: =SUM(J11:J15) -> 2.5831773e+09 | K16: =SUM(K11:K15) -> 2.2863497e+09 | L16: =SUM(L11:L15) -> 2.6499041e+08 | M16: =SUM(M11:M15) -> 31837216 | O16: =SUM(O11:O15) -> 2.3848911e+09 | P16: 2.0962812e+09 | Q16: 2.4668451e+08 | R16: 41925362
B17: Add (Deduct) Changes in net assets/equity during the Year
C18: Adjustment of net revenue recognized directly in net assets/equity | E18: =F18+G18+H18 -> 0 | F18: 0 | G18: 0 | H18: 0 | J18: =K18+L18+M18 -> 0 | K18: 0 | L18: 0 | M18: 0 | O18: =P18+Q18+R18 -> 0 | P18: 0 | Q18: 0 | R18: 0
C19: Unrealized Gain/(Loss) from Changes in the Fair Value of Financial Assets | E19: =F19+G19+H19 -> 0 | F19: 0 | G19: 0 | H19: 0 | J19: =K19+L19+M19 -> 0 | K19: 0 | L19: 0 | M19: 0 | O19: =P19+Q19+R19 -> 0 | P19: 0 | Q19: 0 | R19: 0
C20: Suplus (Deficit) for the period | E20: =F20+G20+H20 -> 4.2307988e+08 | F20: =B!G328 -> 2.8236966e+08 | G20: =B!H328 -> 43668115 | H20: =B!I328 -> 97042105 | J20: =K20+L20+M20 -> 3.6645493e+08 | K20: =+B!L328 -> 3.3004831e+08 | L20: =+B!M328 -> 31535552 | M20: =+B!N328 -> 4871072.4 | O20: =P20+Q20+R20 -> 3.8950977e+08 | P20: 3.6847942e+08 | Q20: 29956769 | R20: -8926420.5
C21: Total recognized revenue and expenses for the period | E21: =SUM(E18:E20) -> 4.2307988e+08 | F21: =SUM(F18:F20) -> 2.8236966e+08 | G21: =SUM(G18:G20) -> 43668115 | H21: =SUM(H18:H20) -> 97042105 | J21: =SUM(J18:J20) -> 3.6645493e+08 | K21: =SUM(K18:K20) -> 3.3004831e+08 | L21: =SUM(L18:L20) -> 31535552 | M21: =SUM(M18:M20) -> 4871072.4 | O21: =SUM(O18:O20) -> 3.8950977e+08 | P21: 3.6847942e+08 | Q21: 29956769 | R21: -8926420.5
B22: Add (Deduct): Others | E22: =F22+G22+H22 -> 0 | F22: 0 | G22: 0 | H22: 0 | J22: =K22+L22+M22 -> 0 | K22: 0 | L22: 0 | M22: 0 | O22: =P22+Q22+R22 -> 0 | P22: 0 | Q22: 0 | R22: 0
D23: Transfer of Completed Infra. Projects/PPE to Registry | E23: =F23+G23+H23 -> 0 | J23: =K23+L23+M23 -> 0 | O23: =P23+Q23+R23 -> 0
D24: Transfer of Funds (from) / to Other Funds | E24: =F24+G24+H24 -> 0 | J24: =K24+L24+M24 -> 0 | O24: =P24+Q24+R24 -> 0
D25: Prior Period Adjustments | E25: =F25+G25+H25 -> 0 | J25: =K25+L25+M25 -> 0 | O25: =P25+Q25+R25 -> 0
D26: Other Adjustments | E26: =F26+G26+H26 -> 0 | J26: =K26+L26+M26 -> 0 | O26: =P26+Q26+R26 -> 0
B27: Balance at December 31 | E27: =E16+E21+E23+E24+E25+E26 -> 3.0270564e+09 | F27: =F16+F21+F23+F24+F25+F26 -> 2.7351325e+09 | G27: =G16+G21+G23+G24+G25+G26 -> 1.5957973e+08 | H27: =H16+H21+H23+H24+H25+H26 -> 1.3234422e+08 | J27: =J16+J21+J23+J24+J25+J26 -> 2.9496322e+09 | K27: =K16+K21+K23+K24+K25+K26 -> 2.616398e+09 | L27: =L16+L21+L23+L24+L25+L26 -> 2.9652596e+08 | M27: =M16+M21+M23+M24+M25+M26 -> 36708289 | O27: =O16+O21+O23+O24+O25+O26 -> 2.7744008e+09 | P27: 2.4647606e+09 | Q27: 2.7664128e+08 | R27: 32998941
A29: PER FINANCIAL PERFORMANCE (Surplus/(Deficit) | J29: =K29+L29+M29 -> 3.6645493e+08 | K29: =B!L328 -> 3.3004831e+08 | L29: =B!M328 -> 31535552 | M29: =B!N328 -> 4871072.4 | O29: =P29+Q29+R29 -> 3.8950977e+08 | P29: =B!Q328 -> 3.6847942e+08 | Q29: =B!R328 -> 29956769 | R29: =B!S328 -> -8926420.5
A30: DIFFERENCE | J30: =K30+L30+M30 -> 0 | K30: =SUM(K20-K29) -> 0 | L30: =SUM(L20-L29) -> 0 | M30: =SUM(M20-M29) -> 0 | O30: =P30+Q30+R30 -> 2.3469329e-07 | P30: =SUM(P20-P29) -> 2.3841858e-07 | Q30: =SUM(Q20-Q29) -> -3.7252903e-09 | R30: =SUM(R20-R29) -> 0
A32: PER FINANCIAL POSITIONS (Net Asset/Equity) | J32: =K32+L32+M32 -> 2.9496322e+09 | K32: =A!L545 -> 2.616398e+09 | L32: =A!M545 -> 2.9652596e+08 | M32: =A!N545 -> 36708289 | O32: =P32+Q32+R32 -> 2.7744008e+09 | P32: =A!Q545 -> 2.4647606e+09 | Q32: =A!R545 -> 2.7664128e+08 | R32: =A!S545 -> 32998941
A33: DIFFERENCE | J33: =K33+L33+M33 -> 0 | K33: =SUM(K27-K32) -> 0 | L33: =SUM(L27-L32) -> 0 | M33: =SUM(M27-M32) -> 0 | O33: =P33+Q33+R33 -> 0 | P33: =SUM(P27-P32) -> 0 | Q33: =SUM(Q27-Q32) -> 0 | R33: =SUM(R27-R32) -> 0

Sheet D
A1: City Government of Panabo
A2: CONSOLIDATED STATEMENT OF CASH FLOWS (BY FUND)
A3: For the Year Ended December 31, 2021
A4: (With Comparative figures in 2020)
A5: (In Philippine Peso)
A7: PARTICULARS | F7: 2021 | K7: 2020 | P7: 2019
F8: TOTAL | G8: GF | H8: SEF | I8: TF | K8: TOTAL | L8: GF | M8: SEF | N8: TF | P8: TOTAL | Q8: GF | R8: SEF | S8: TF
A9: Cash Flow from Operating Activities
B10: Cash Inflows
C11: Collection from taxpayers | F11: =G11+H11+I11 -> 2.9727308e+08 | G11: 2.3382968e+08 | H11: 63443403 | I11: 0 | K11: =L11+M11+N11 -> 2.8823036e+08 | L11: 2.2968414e+08 | M11: 58546218 | N11: 0 | P11: =Q11+R11+S11 -> 2.8880623e+08 | Q11: 2.272369e+08 | R11: 61569328 | S11: 0
C12: Share from Internal Revenue Allotment | F12: =G12+H12+I12 -> 889216030 | G12: 889216030 | H12: 0 | I12: 0 | K12: =L12+M12+N12 -> 6.6373796e+08 | L12: 6.6373796e+08 | M12: 0 | N12: 0 | P12: =Q12+R12+S12 -> 6.628859e+08 | Q12: 6.628859e+08 | R12: 0 | S12: 0
C13: Receipts from business/service income | F13: =G13+H13+I13 -> 1.0571275e+08 | G13: 1.0571275e+08 | H13: 0 | I13: 0 | K13: =L13+M13+N13 -> 1.1585381e+08 | L13: 1.1585381e+08 | M13: 0 | N13: 0 | P13: =Q13+R13+S13 -> 1.4601479e+08 | Q13: 1.4601479e+08 | R13: 0 | S13: 0
C14: Interest Income | F14: =G14+H14+I14 -> 385197.82 | G14: 349917.16 | H14: 35280.66 | I14: 0 | K14: =L14+M14+N14 -> 2641158.5 | L14: 2578718.4 | M14: 62440.02 | N14: 0 | P14: =Q14+R14+S14 -> 1296924 | Q14: 1233224 | R14: 63699.97 | S14: 0
C15: Other Receipts | F15: =G15+H15+I15 -> 1.2311718e+09 | G15: 7.4069827e+08 | H15: 1339435.2 | I15: 4.8913407e+08 | K15: =L15+M15+N15 -> 9.4958274e+08 | L15: 6.4122837e+08 | M15: 283663.95 | N15: 3.0807071e+08 | P15: =Q15+R15+S15 -> 3.5907348e+08 | Q15: 3.1838397e+08 | R15: 4544077.9 | S15: 36145439
B16: Total Cash Inflows | F16: =G16+H16+I16 -> 2.5237588e+09 | G16: =SUM(G11:G15) -> 1.9698066e+09 | H16: =SUM(H11:H15) -> 64818119 | I16: =SUM(I11:I15) -> 4.8913407e+08 | K16: =L16+M16+N16 -> 2.020046e+09 | L16: =SUM(L11:L15) -> 1.653083e+09 | M16: =SUM(M11:M15) -> 58892322 | N16: =SUM(N11:N15) -> 3.0807071e+08 | P16: =Q16+R16+S16 -> 1.4580773e+09 | Q16: 1.3557548e+09 | R16: 66177106 | S16: 36145439
B17: Cash OutFlows
C18: Payments of expenses | F18: =G18+H18+I18 -> 3.3530866e+08 | G18: 3.1948847e+08 | H18: 11339962 | I18: 4480229.1 | K18: =L18+M18+N18 -> 4.6311603e+08 | L18: 2.8412163e+08 | M18: 8271822.5 | N18: 1.7072258e+08 | P18: =Q18+R18+S18 -> 3.1166237e+08 | Q18: 2.9964603e+08 | R18: 10012852 | S18: 2003488.6
C19: Payment to suppliers and creditors | F19: =G19+H19+I19 -> 1.8193685e+08 | G19: 1.5999827e+08 | H19: 8656964.6 | I19: 13281610 | K19: =L19+M19+N19 -> 1.9567671e+08 | L19: 1.7764442e+08 | M19: 9258431.6 | N19: 8773858.2 | P19: =Q19+R19+S19 -> 82428377 | Q19: 72626546 | R19: 8002196 | S19: 1799634.1
C20: Payment to employees | F20: =G20+H20+I20 -> 2.581936e+08 | G20: 2.581936e+08 | H20: 0 | I20: 0 | K20: =L20+M20+N20 -> 2.6055775e+08 | L20: 2.6025207e+08 | M20: 0 | N20: 305675.97 | P20: =Q20+R20+S20 -> 2.1147304e+08 | Q20: 2.1147304e+08 | R20: 0 | S20: 0
C21: Interest Expense | F21: =G21+H21+I21 -> 10419963 | G21: 10419963 | H21: 0 | I21: 0 | K21: =L21+M21+N21 -> 11780899 | L21: 11780899 | M21: 0 | N21: 0 | P21: =Q21+R21+S21 -> 11009435 | Q21: 10907855 | R21: 101579.81 | S21: 0
C22: Other Expenses | F22: =G22+H22+I22 -> 9.816656e+08 | G22: 9.2922932e+08 | H22: 11535297 | I22: 40900978 | K22: =L22+M22+N22 -> 6.8148464e+08 | L22: 6.4295289e+08 | M22: 6954738.7 | N22: 31577006 | P22: =Q22+R22+S22 -> 4.7248982e+08 | Q22: 4.5184384e+08 | R22: 9296907.4 | S22: 11349068
B23: Total Cash Outflows | F23: =G23+H23+I23 -> 1.7675247e+09 | G23: =SUM(G18:G22) -> 1.6773296e+09 | H23: =SUM(H18:H22) -> 31532224 | I23: =SUM(I18:I22) -> 58662817 | K23: =L23+M23+N23 -> 1.612616e+09 | L23: =SUM(L18:L22) -> 1.3767519e+09 | M23: =SUM(M18:M22) -> 24484993 | N23: =SUM(N18:N22) -> 2.1137912e+08 | P23: =Q23+R23+S23 -> 1.089063e+09 | Q23: 1.0464973e+09 | R23: 27413535 | S23: 15152191
A24: Net Cash Flows from Operating Activities | F24: =G24+H24+I24 -> 7.5623416e+08 | G24: =G16-G23 -> 2.9247702e+08 | H24: =H16-H23 -> 33285895 | I24: =I16-I23 -> 4.3047125e+08 | K24: =L24+M24+N24 -> 4.0743001e+08 | L24: =L16-L23 -> 2.763311e+08 | M24: =M16-M23 -> 34407329 | N24: =N16-N23 -> 96691584 | P24: =Q24+R24+S24 -> 3.6901428e+08 | Q24: 3.0925746e+08 | R24: 38763571 | S24: 20993248
A25: Cash Flow from Investing Activities
B26: Cash Inflows
C27: Proceeds from Sale of PPE | F27: =G27+H27+I27 -> 0 | G27: 0 | H27: 0 | I27: 0 | K27: =L27+M27+N27 -> 0 | L27: 0 | M27: 0 | N27: 0 | P27: =Q27+R27+S27 -> 10280.05 | Q27: 10280.05 | R27: 0 | S27: 0
B28: Total Cash Inflows | F28: =G28+H28+I28 -> 0 | G28: 0 | H28: 0 | I28: 0 | K28: =L28+M28+N28 -> 0 | L28: 0 | M28: 0 | N28: 0 | P28: =Q28+R28+S28 -> 10280.05 | Q28: 10280.05 | R28: 0 | S28: 0
B29: Cash OutFlows
C30: Purchase/Construction of Property, Plant and Equipment | F30: =G30+H30+I30 -> 5.3812719e+08 | G30: 4.087661e+08 | H30: 31337980 | I30: 98023106 | K30: =L30+M30+N30 -> 2.5541602e+08 | L30: 2.2989347e+08 | M30: 11311922 | N30: 14210634 | P30: =Q30+R30+S30 -> 2.8469323e+08 | Q30: 2.2671978e+08 | R30: 37267027 | S30: 20706419
B31: Total Cash Outflows | F31: =G31+H31+I31 -> 5.3812719e+08 | G31: =G30 -> 4.087661e+08 | H31: =H30 -> 31337980 | I31: =I30 -> 98023106 | K31: =L31+M31+N31 -> 2.5541602e+08 | L31: =L30 -> 2.2989347e+08 | M31: =M30 -> 11311922 | N31: =N30 -> 14210634 | P31: =Q31+R31+S31 -> 2.8469323e+08 | Q31: 2.2671978e+08 | R31: 37267027 | S31: 20706419
A32: Net Cash Flows from Investing Activities | F32: =G32+H32+I32 -> -5.3812719e+08 | G32: =-G31 -> -4.087661e+08 | H32: =-H31 -> -31337980 | I32: =-I31 -> -98023106 | K32: =L32+M32+N32 -> -2.5541602e+08 | L32: =-L31 -> -2.2989347e+08 | M32: =-M31 -> -11311922 | N32: =-N31 -> -14210634 | P32: =Q32+R32+S32 -> -2.8468295e+08 | Q32: -2.267095e+08 | R32: -37267027 | S32: -20706419
A33: Cash Flow from Financing Activities
B34: Cash Inflows
C35: Proceeds from Issuance of Bills and Bonds | F35: =G35+H35+I35 -> 0 | K35: =L35+M35+N35 -> 0 | P35: =Q35+R35+S35 -> 0
C36: Proceeds from Domestic and Foreign Loans | F36: =G36+H36+I36 -> 9564783 | G36: 9564783 | H36: 0 | I36: 0 | K36: =L36+M36+N36 -> 1.0993888e+08 | L36: 1.0993888e+08 | M36: 0 | N36: 0 | P36: =Q36+R36+S36 -> 94028150 | Q36: 94028150 | R36: 0 | S36: 0
B37: Total Cash Inflows | F37: =G37+H37+I37 -> 9564783 | G37: =SUM(G35:G36) -> 9564783 | H37: =SUM(H35:H36) -> 0 | I37: =SUM(I35:I36) -> 0 | K37: =L37+M37+N37 -> 1.0993888e+08 | L37: =SUM(L35:L36) -> 1.0993888e+08 | M37: =SUM(M35:M36) -> 0 | N37: =SUM(N35:N36) -> 0 | P37: =Q37+R37+S37 -> 94028150 | Q37: 94028150 | R37: 0 | S37: 0
B38: Cash OutFlows
C39: Payment of Long-Term Liabilities | F39: =G39+H39+I39 -> 26694021 | G39: 26694021 | H39: 0 | I39: 0 | K39: =L39+M39+N39 -> 27389241 | L39: 27389241 | M39: 0 | N39: 0 | P39: =Q39+R39+S39 -> 28330579 | Q39: 26709270 | R39: 1621309.1 | S39: 0
C40: Retirement/Redemption of debt securities | F40: =G40+H40+I40 -> 0 | K40: =L40+M40+N40 -> 0 | P40: =Q40+R40+S40 -> 0
C41: Payment of loan amortization | F41: =G41+H41+I41 -> 0 | K41: =L41+M41+N41 -> 0 | P41: =Q41+R41+S41 -> 0
...

Sheet E
A1: CITY GOVERNMENT OF PANABO
A2: Statement of Comparison of Budget and Actual Amounts
A3: For the Year Ended December 31, 2021
A4: (With Comparative figures in 2020)
A5: (In Philippine Peso)
A7: Particulars | F7: Notes | G7: 2021 | R7: 2020 | AA7: 2019
H8: Budgeted | K8: Difference | P8: Difference | R8: Budgeted | U8: Difference | Z8: Difference | AA8: Budgeted | AE8: Difference | AJ8: Difference
H9: Amounts | K9: Original and | N9: Actual | P9: Final Budget | R9: Amounts | U9: Original and | X9: Actual | Z9: Final Budget | AA9: Amounts | AE9: Original and | AH9: Actual | AJ9: Final Budget
H10: Original | J10: Final | K10: Final Budget | N10: Amounts | P10: and Actual | R10: Original | T10: Final | U10: Final Budget | X10: Amounts | Z10: and Actual | AB10: Original | AD10: Final | AE10: Final Budget | AH10: Amounts | AJ10: and Actual
A12: General Fund
A13: Revenue
B14: A. Local Sources
C15: 1. Tax Revenue
D16: a. Tax Revenue - Property | H16: 48300000 | J16: 48300000 | L16: =H16-J16 -> 0 | N16: 40423521 | P16: =J16-N16 -> 7876479.3 | R16: 40500000 | T16: 40500000 | V16: =R16-T16 -> 0 | X16: 31653941 | Z16: =T16-X16 -> 8846058.8 | AB16: 36000000 | AD16: 36000000 | AF16: =AB16-AD16 -> 0 | AH16: 37314897 | AJ16: =AD16-AH16 -> -1314896.7
D17: b. Tax Revenue - Goods and Services | H17: 154170000 | J17: 154170000 | L17: =H17-J17 -> 0 | N17: 1.7229295e+08 | P17: =J17-N17 -> -18122948 | R17: 146850000 | T17: 146850000 | V17: =R17-T17 -> 0 | X17: 1.7425452e+08 | Z17: =T17-X17 -> -27404524 | AB17: 138668000 | AD17: 138668000 | AF17: =AB17-AD17 -> 0 | AH17: 1.6515343e+08 | AJ17: =AD17-AH17 -> -26485428
D18: c. Other Local Taxes | H18: 9770000 | J18: 9770000 | L18: =H18-J18 -> 0 | N18: 13436740 | P18: =J18-N18 -> -3666739.5 | R18: 2200000 | T18: 2200000 | V18: =R18-T18 -> 0 | X18: 12455043 | Z18: =T18-X18 -> -10255043 | AB18: 5200000 | AD18: 5200000 | AF18: =AB18-AD18 -> 0 | AH18: 13204978 | AJ18: =AD18-AH18 -> -8004978.5
C19: Total Tax Revenue | H19: =SUM(H16:H18) -> 212240000 | J19: =SUM(J16:J18) -> 212240000 | L19: =SUM(L16:L18) -> 0 | N19: =SUM(N16:N18) -> 2.2615321e+08 | P19: =SUM(P16:P18) -> -13913208 | R19: =SUM(R16:R18) -> 189550000 | T19: =SUM(T16:T18) -> 189550000 | V19: =SUM(V16:V18) -> 0 | X19: =SUM(X16:X18) -> 2.1836351e+08 | Z19: =SUM(Z16:Z18) -> -28813508 | AB19: =SUM(AB16:AB18) -> 179868000 | AD19: =SUM(AD16:AD18) -> 179868000 | AF19: =SUM(AF16:AF18) -> 0 | AH19: =SUM(AH16:AH18) -> 2.156733e+08 | AJ19: =SUM(AJ16:AJ18) -> -35805303
C20: 2. Non-Tax Revenue
D21: a. Service Income | H21: 54570000 | J21: 54570000 | L21: =H21-J21 -> 0 | N21: 51945013 | P21: =J21-N21 -> 2624987.3 | R21: 53991350 | T21: 53991350 | V21: =R21-T21 -> 0 | X21: 47059884 | Z21: =T21-X21 -> 6931465.8 | AB21: 42342950 | AD21: 43089070 | AF21: =AB21-AD21 -> -746120.15 | AH21: 53617271 | AJ21: =AD21-AH21 -> -10528201
D22: b. Business Income | H22: 97051835 | J22: 97051835 | L22: =H22-J22 -> 0 | N22: 90091676 | P22: =J22-N22 -> 6960159.3 | R22: 81149298 | T22: 86897710 | V22: =R22-T22 -> -5748411.7 | X22: 70689542 | Z22: =T22-X22 -> 16208167 | AB22: 80379756 | AD22: 83715756 | AF22: =AB22-AD22 -> -3336000 | AH22: 94104604 | AJ22: =AD22-AH22 -> -10388848
D23: c. Other Income and Receipts | H23: 4.6198823e+08 | J23: 5.8996691e+08 | L23: =H23-J23 -> -1.2797868e+08 | N23: 3.8883641e+08 | P23: =J23-N23 -> 2.011305e+08 | R23: 7300000 | T23: 4.1548309e+08 | V23: =R23-T23 -> -4.0818309e+08 | X23: 625391.86 | Z23: =T23-X23 -> 4.148577e+08 | AB23: 1110000 | AD23: 2.4468154e+08 | AF23: =AB23-AD23 -> -2.4357154e+08 | AH23: 3751280.3 | AJ23: =AD23-AH23 -> 2.4093026e+08
C24: Total Non-Tax Revenue | H24: =SUM(H21:H23) -> 6.1361007e+08 | J24: =SUM(J21:J23) -> 7.4158874e+08 | L24: =SUM(L21:L23) -> -1.2797868e+08 | N24: =SUM(N21:N23) -> 5.308731e+08 | P24: =SUM(P21:P23) -> 2.1071565e+08 | R24: =SUM(R21:R23) -> 1.4244065e+08 | T24: =SUM(T21:T23) -> 5.5637215e+08 | V24: =SUM(V21:V23) -> -4.1393151e+08 | X24: =SUM(X21:X23) -> 1.1837482e+08 | Z24: =SUM(Z21:Z23) -> 4.3799734e+08 | AB24: =SUM(AB21:AB23) -> 1.2383271e+08 | AD24: =SUM(AD21:AD23) -> 3.7148637e+08 | AF24: =SUM(AF21:AF23) -> -2.4765366e+08 | AH24: =SUM(AH21:AH23) -> 151473155 | AJ24: =SUM(AJ21:AJ23) -> 2.2001321e+08
B25: B. External Sources
C26: 1. Share from the National Internal Revenue Taxes (IRA) | H26: 829672451 | J26: 889216030 | L26: =H26-J26 -> -59543579 | N26: 889216030 | P26: =J26-N26 -> 0 | R26: 734827207 | T26: 829672451 | V26: =R26-T26 -> -94845244 | X26: 829672451 | Z26: =T26-X26 -> 0 | AB26: 734827207 | AD26: 739212765 | AF26: =AB26-AD26 -> -4385558 | AH26: 7.3921276e+08 | AJ26: =AD26-AH26 -> 0
C27: 2. Share from GOCCs | AF27: =AB27-AD27 -> 0 | AJ27: =AD27-AH27 -> 0
D28: a. Share from Ecozone | E28: Share from PCSO | H28: 700000 | J28: 700000 | L28: =H28-J28 -> 0 | N28: 1192785.3 | P28: =J28-N28 -> -492785.32 | R28: 650000 | V28: =R28-T28 -> 650000 | X28: 218580.68 | Z28: =T28-X28 -> -218580.68 | AB28: 450000 | AD28: 450000 | AF28: =AB28-AD28 -> 0 | AH28: 637969.8 | AJ28: =AD28-AH28 -> -187969.8
C29: 3. Other Shares from National Tax Collections | AF29: =AB29-AD29 -> 0 | AH29: =AH30 -> 131334.6 | AJ29: =AD29-AH29 -> -131334.6
D30: a. Share from Ecozone | L30: 0 | N30: 72609 | P30: =J30-N30 -> -72609 | V30: 0 | X30: 588344.53 | Z30: =T30-X30 -> -588344.53 | AF30: =AB30-AD30 -> 0 | AH30: 131334.6 | AJ30: =AD30-AH30 -> -131334.6
D31: b. Share from EVAT | L31: 0 | P31: 0 | V31: 0 | X31: 0 | Z31: 0 | AF31: =AB31-AD31 -> 0 | AJ31: =AD31-AH31 -> 0
D32: c. Share from National Wealth | L32: 0 | P32: =J32-N32 -> 0 | V32: 0 | X32: 131344.5 | Z32: =T32-X32 -> -131344.5 | AF32: =AB32-AD32 -> 0 | AJ32: =AD32-AH32 -> 0
D33: d. Share from Tobacco Excise Tax | L33: 0 | P33: 0 | V33: 0 | X33: 0 | Z33: 0 | AF33: =AB33-AD33 -> 0 | AJ33: =AD33-AH33 -> 0
C34: 4. Other Receipts | AF34: =AB34-AD34 -> 0 | AJ34: =AD34-AH34 -> 0
D35: a. Grants and Donations | H35: 0 | J35: 0 | L35: =H35-J35 -> 0 | P35: =J35-N35 -> 0 | T35: 69139371 | V35: =R35-T35 -> -69139371 | X35: 69139371 | Z35: =T35-X35 -> 0 | AF35: =AB35-AD35 -> 0 | AJ35: =AD35-AH35 -> 0
D36: b. Other Subsidy Income | H36: 0 | J36: 15122372 | L36: =H36-J36 -> -15122372 | N36: 15122372 | P36: =J36-N36 -> 0 | R36: 3936955.6 | T36: 5111182.1 | V36: =R36-T36 -> -1174226.5 | X36: 9681863.8 | Z36: =T36-X36 -> -4570681.7 | AF36: =AB36-AD36 -> 0 | AJ36: =AD36-AH36 -> 0
C37: 5. Inter-local Transfer | L37: 0 | P37: =J37-N37 -> 0 | V37: 0 | X37: 0 | Z37: =T37-X37 -> 0 | AD37: 11696870 | AF37: =AB37-AD37 -> -11696870 | AH37: 12932884 | AJ37: =AD37-AH37 -> -1236013.8
C38: 6. Capital /Investment Receipts | P38: 0 | Z38: 0 | AF38: =AB38-AD38 -> 0 | AJ38: =AD38-AH38 -> 0
D39: a. Sale of Capital Assets | H39: 0 | J39: 0 | L39: 0 | P39: 0 | R39: 0 | T39: 0 | V39: 0 | X39: 0 | Z39: 0 | AF39: =AB39-AD39 -> 0 | AJ39: =AD39-AH39 -> 0
D40: b. Sale of Investments | H40: 0 | J40: 0 | L40: 0 | P40: 0 | R40: 0 | T40: 0 | V40: 0 | X40: 0 | Z40: 0 | AF40: =AB40-AD40 -> 0 | AJ40: =AD40-AH40 -> 0
D41: c. Proceeds from Collections of Loan Receivable | H41: 0 | L41: 0 | N41: 549735 | P41: 0 | R41: 0 | V41: 0 | X41: 0 | Z41: 0 | AF41: =AB41-AD41 -> 0 | AJ41: =AD41-AH41 -> 0
B42: C. Receipts from Borrowings | J42: 600000000 | L42: 0 | N42: 9564783 | P42: =J42-N42 -> 590435217 | V42: 0 | X42: 1.0993888e+08 | Z42: =T42-X42 -> -1.0993888e+08 | AF42: =AB42-AD42 -> 0 | AH42: 94028150 | AJ42: =AD42-AH42 -> -94028150
...

Sheet F
A1: City Government of Panabo | D1: Annex F
A2: As of November 30, 2021
A4: Schedule of reconciling items
A6: Account No. | B6: Date | C6: Check No. | D6: Amount
A7: Unrecorded Paid Vouchers
A8: 1742-1006-90 | B8: 43620 | C8: 1395928 | D8: 1200
B9: 44266 | C9: 1482772 | D9: 187500
B10: 44460 | C10: 1514546 | D10: 2230
B11: 44524 | C11: 1515374 | D11: 10000
A12: 1742-1007-03 | B12: 44524 | C12: 1506411 | D12: 46120
A13: 1742-1006-81 | B13: 44529 | C13: 1440965 | D13: 2200
A14: 1742-1037-29 | B14: 44494 | C14: 1459199 | D14: 35493
A15: 1742-1008-35 | B15: 44526 | C15: 1507048 | D15: 228006.7
B16: 44518 | C16: 1507065 | D16: 4032.77
B17: 44523 | C17: 1507082 | D17: 33692.85
B18: 44525 | C18: 1507088 | D18: 122159
B19: 44525 | C19: 1507089 | D19: 49144.97
B20: 44526 | C20: 1507092 | D20: 2300
B21: 44526 | C21: 1507093 | D21: 11600
B22: 44529 | C22: 1507094 | D22: 17861.11
A23: 1742-1037-10 | B23: 44525 | C23: 1491872 | D23: 17458.36
B24: 44525 | C24: 1491872 | D24: 31196
B25: 44495 | C25: 1491840 | D25: 800
B26: 44495 | C26: 1491841 | D26: 200
A27: 1742-1037-96 | B27: 44524 | C27: 1406994 | D27: 2286744.3
B28: Total | D28: =SUM(D8:D27) -> 3089939.1

Sheet G
A1: City Government of Panabo | C1: Annex G
A2: As at December 31, 2021
A4: Schedule of reconciling items
A6: Account No. | B6: Date | C6: Amount
A7: Unrecorded Credit Memo
A8: 1742-1006-90 | B8: CM Ordinary dated 12-03-19 | C8: 40000
B9: CM Ordinary dated 05-25-21 | C9: 6145
B10: CM Ordinary dated 09-21-21 | C10: 200
B11: CM Ordinary remittance mgt Dept. dated 11-29-21 | C11: 150
B12: CM Ordinary dated 11-29-21 | C12: 11
A13: 1742-1007-03 | B13: CM- PYRL/OTHRS dtd 11-28-19 | C13: 30000
A14: 1742-1033-46 | B14: CM-ordinary dtd 8-13-18 | C14: 750
A15: 1742-1037-29 | B15: CM Ordinary dtd 8-13-18 | C15: 750
A16: 1742-1044-07 | B16: CM-auto reansfer | C16: 100
A17: 1742-1043-50 | B17: CA-CM ordinary dtd 1-4-19 | C17: 50000
A18: 1742-1066-55 | B18: CM-Ordinary dtd 9/29/20 | C18: 20000
B19: CM-Ordinary dtd 9/230/20 | C19: 2800
B20: Sub-total | C20: =SUM(C8:C19) -> 150906
A21: Unrecorded Debit Memo
A22: 1742-1006-90 | B22: Authorized transfer dtd 6-10-14 | C22: 2564
B23: DM Ordinary dated 7-14-14 | C23: 2995
B24: DM Ordinary dated 5-16-17 | C24: 1515
B25: DM Ordinary dated 10-19-18 | C25: 2256
B26: DM Ordinary dated 11/16-18 | C26: 1995
B27: DM Ordinary dated 1-29-19 | C27: 2258
B28: DM Ordinary dated 3-20-19 | C28: 2250
B29: DM Ordinary dated 4-12-19 | C29: 2251
B30: DMRT dated 4-10-19 | C30: 27812.96
B31: DM Ordinary dated 7-16-19 | C31: 6855
B32: DM Ordinary dated 9-29-20 | C32: 20000
B33: DM Ordinary dated 10-4-21 | C33: 46579.98
A34: 1742-1006-81 | B34: DM Ordinary dated 11-27-19 | C34: 3000
B35: DMTRA CA DM TRF AUTH dtd 7-13-20 | C35: 246277.89
A36: 1742-1007-03 | B36: DM-ordinary dtd 10-19-18 | C36: 1800
B37: DMTRA CA DM TRF AUTH dtd 8/27/21 | C37: 81000
A38: 1742-1033-46 | B38: DM-ordinary dtd 11-27-19 | C38: 1800
B39: DM-Ordinary dtd 10-5-21 | C39: 1800
A40: 1742-1037-29 | B40: DM-ordinary dtd 7-8-21 | C40: 1800
A41: 1742-1008-35 | B41: DM stubs checkbooks @360 | C41: 1080
B42: DM - ordinary dtd 10-5-21 | C42: 3000
...

Sheet H
A1: Annex A: Total COVID-19 Vaccines Received by the City of Panabo and its Ending Inventory | M1: Annex H
A2: As of December 31, 2021
E3: Per GSO | H3: Per Audit | M3: Remarks
E4: Received | H4: Received | K4: Ending balance
A5: DATE | B5: PTR No. | C5: Vaccine Brand | D5: Received From | E5: Qty | F5: Price | G5: Total | H5: Qty | I5: Price | J5: Total | K5: Qty | L5: Total
E6: a | F6: b | G6: (a x b) | H6: a | I6: b | J6: (a x b) | K6: c | L6: (c x b)
A7: First Dose
A8: 44266 | B8: CVS-21-03-03 | C8: Astrazeneca | D8: PHO | E8: 22 | F8: 1942.8 | G8: 42741.6 | H8: 22 | I8: 1942.8 | J8: 42741.6 | L8: 0
A9: 44266 | B9: CVS-21-03-03 | C9: Sinovac | D9: PHO | H9: 600 | I9: 714.37 | J9: 428622 | L9: 0 | M9: As per PTR, 600 units of Sinovac with unit price of P714.37, was erroneously totaled as P214,311.00.
A10: 44271 | B10: 21-V-03-20 | C10: Sinovac | D10: PHO | E10: 64 | F10: 714.37 | G10: 45719.68 | H10: 64 | I10: 714.37 | J10: 45719.68 | L10: 0
A11: 44277 | B11: 21-V-03-69 | C11: Astrazeneca | D11: PHO | E11: 70 | F11: 1942.8 | G11: 135996 | H11: 70 | I11: 1942.8 | J11: 135996 | L11: 0
A12: 44292 | B12: V-21-04-16 | C12: Sinovac | D12: PHO | E12: 150 | F12: 715.55 | G12: 107332.5 | H12: 150 | I12: 715.55 | J12: 107332.5 | L12: 0
A13: 44298 | B13: V-21-04-19 | C13: Sinovac | D13: PHO | E13: 303 | F13: 700 | G13: 212100 | H13: 303 | I13: 700 | J13: 212100 | L13: 0
A14: 44306 | B14: V-21-04-35 | C14: Sinovac | D14: PHO | E14: 527 | F14: 683.2 | G14: 360046.4 | H14: 527 | I14: 683.2 | J14: 360046.4 | L14: 0
A15: 44327 | B15: V-21-05-18 | C15: Sinovac | D15: PHO | E15: 700 | F15: 683.2 | G15: 478240 | H15: 700 | I15: 683.2 | J15: 478240 | L15: 0
A16: 44328 | B16: V-21-05-46 | C16: Astrazeneca | D16: PHO | E16: 190 | F16: 1911.2 | G16: 363128 | H16: 190 | I16: 1911.2 | J16: 363128 | L16: 0
A17: 44337 | B17: V-21-05-61 | C17: Sinovac | D17: PHO | E17: 1000 | F17: 683.2 | G17: 683200 | H17: 1000 | I17: 683.2 | J17: 683200 | L17: 0
A18: 44337 | B18: V-21-05-72 | C18: Astrazeneca | D18: PHO | E18: 200 | F18: 1911.2 | G18: 382240 | H18: 200 | I18: 1911.2 | J18: 382240 | L18: 0
A19: 44375 | B19: V-21-06-88 | C19: Sinovac | D19: PHO | E19: 1500 | F19: 669.41 | G19: 1004115 | H19: 1500 | I19: 669.41 | J19: 1004115 | L19: 0
A20: 44379 | B20: V-21-07-08 | C20: Sinovac | D20: PHO | E20: 1000 | F20: 669.41 | G20: 669410 | H20: 1000 | I20: 669.41 | J20: 669410 | L20: 0
A21: 44396 | B21: V-21-07-41 | C21: Sinovac | D21: PHO | E21: 1500 | F21: 669.41 | G21: 1004115 | H21: 1500 | I21: 669.41 | J21: 1004115 | L21: 0
... A33: 44453 | B33: V-21-09-79 | C33: Pfizer | D33: PHO | E33: 170 | F33: 1958.82 | G33: 332999.4 | H33: 170 | I33: 1958.82 | J33: 332999.4 | L33: 0
C34: Pfizer | D34: PHO | E34: 230 | F34: 1958.82 | G34: 450528.6 | H34: 230 | I34: 1958.82 | J34: 450528.6 | L34: 0
A35: 44460 | B35: V-21-09-87 | C35: Sinovac | D35: PHO | E35: 3500 | F35: 669.41 | G35: 2342935 | H35: 3500 | I35: 669.41 | J35: 2342935 | L35: 0
A36: 44468 | B36: V-21-09-108 | C36: Pfizer | D36: PHO | E36: 450 | F36: 1958.82 | G36: 881469 | H36: 450 | I36: 1958.82 | J36: 881469 | L36: 0
A37: 44474 | B37: V-21-10-14 | C37: Sinovac | D37: PHO | E37: 2000 | F37: 669.41 | G37: 1338820 | H37: 2000 | I37: 669.41 | J37: 1338820 | L37: 0
A38: 44477 | B38: V-21-10-24 | C38: Pfizer | D38: PHO | E38: 350 | F38: 1958.82 | G38: 685587 | H38: 350 | I38: 2017.3 | J38: 706055 | L38: 0
A39: 44487 | B39: V-21-10-32 | C39: Pfizer | D39: PHO | E39: 350 | F39: 1958.82 | G39: 685587 | H39: 1200 | I39: 2017.3 | J39: 2420760 | L39: 0
A40: 44494 | B40: V-21-10-66 | C40: Sinovac | D40: PHO | E40: 1000 | F40: 669.41 | G40: 669410 | H40: 1000 | I40: 669.41 | J40: 669410 | L40: 0
A41: 44494 | B41: V-21-10-69 | C41: Sinovac | D41: PHO | E41: 2500 | F41: 669.41 | G41: 1673525 | H41: 2500 | I41: 669.41 | J41: 1673525 | L41: 0
A42: 44495 | B42: V-21-10-74 | C42: Moderna | D42: PHO | E42: 44 | F42: 2098.23 | G42: 92322.12 | H42: 44 | I42: 2098.23 | J42: 92322.12 | L42: 0
A43: 44495 | B43: V-21-10-75 | C43: Pfizer | D43: PHO | E43: 1365 | F43: 2017.3 | G43: 2753614.5 | H43: 1365 | I43: 2017.3 | J43: 2753614.5 | L43: 0
A44: 11/0/2021 | B44: 21-V-11-107 | C44: Astrazeneca | D44: DOH RO XI | E44: 170 | F44: 2021.24 | G44: 343610.8 | H44: 170 | I44: 2021.24 | J44: 343610.8 | L44: 0
A45: 44502 | B45: V-21-11-07 | C45: Pfizer | D45: PHO | E45: 1335 | F45: 2017.3 | G45: 2693095.5 | H45: 1335 | I45: 2017.3 | J45: 2693095.5 | L45: 0
A46: 44512 | B46: V-21-11-44 | C46: Pfizer | D46: PHO | E46: 1000 | F46: 2017.3 | G46: 2017300 | H46: 1000 | I46: 2017.3 | J46: 2017300 | L46: 0
A47: 44518 | B47: V-21-11-79 | C47: Sinovac | D47: PHO | E47: 2000 | F47: 669.41 | G47: 1338820 | H47: 2000 | I47: 669.41 | J47: 1338820 | L47: 0
A48: 44518 | B48: V-21-11-84 | C48: Moderna | D48: PHO | E48: 30 | F48: 2098.23 | G48: 62946.9 | H48: 30 | I48: 2098.23 | J48: 62946.9 | L48: 0
A49: 44524 | B49: V-21-11-106 | C49: Sinovac | D49: PHO | E49: 3000 | F49: 334.54 | G49: 1003620 | H49: 3000 | I49: 334.54 | J49: 1003620 | L49: 0
A50: 44529 | B50: V-21-11-119 | C50: Moderna | D50: PHO | E50: 200 | F50: 2098.23 | G50: 419646 | H50: 200 | I50: 2098.23 | J50: 419646 | L50: 0
A51: 44529 | B51: V-21-11-131 | C51: Astrazeneca | D51: PHO | E51: 50 | F51: 2021.24 | G51: 101062 | H51: 50 | I51: 2021.24 | J51: 101062 | L51: 0
...

Sheet I
A1: City Government of Panabo | K1: Annex I
A2: As at December 31, 2021
A4: Schedule of Completed Pojects under CIP accounts
A7: No. | B7: Fund | C7: Account Code | D7: Account Title | E7: Description | F7: Amount | G7: Date Completed | H7: Estimated useful life (in months) | I7: No. of months of depreciation as at year-end | J7: Total depreciation | K7: Asset Account
A8: 1 | B8: General Fund | C8: 269 | D8: CIP-Artesian Wells, Reservoirs, Pumping Stations and Conduits | E8: POW#2019-05-204_INSTALLATION OF WATER SYSTEM WITH RAINWATER HARVESTING FACILITY AT PANABO CITY | F8: 1453309.8 | G8: 44245 | H8: 240 | I8: 10 | J8: =((F8*0.9)/H8)*I8 -> 54499.118 | K8: Artesian Wells, Reservoirs, Pumping Stations and Conduits
D9: Sub-total | F9: =SUM(F8) -> 1453309.8 | J9: =SUM(J8) -> 54499.118
A11: 2 | B11: General Fund | C11: 264 | D11: CIP-Agency Assets | E11: POW#2019-10-001_Site Developmentfor Resettlement Areas - Land Development (DAVIN) @ Brgy. San Franci | F11: 347288.06 | G11: 44469 | H11: 120 | I11: 3 | J11: =((F11*0.9)/H11)*I11 -> 7813.9814 | K11: Land Improvement
A12: =A11+1 -> 3 | B12: General Fund | C12: 264 | D12: CIP-Agency Assets | E12: POW#2019-10-001_Site Developmentfor Resettlement Areas - Land Development (DAVIN) @ Brgy. San Franci | F12: 166134.19 | G12: 40816 | H12: 120 | I12: 120 | J12: =((F12*0.9)/H12)*I12 -> 149520.77 | K12: Land Improvement
A13: =A12+1 -> 4 | B13: General Fund | C13: 264 | D13: CIP-Agency Assets | E13: Cons. of 477 li.m. Perimeter Fence Fronting Cityhall Government Center w/Gate Component @ Brgy. JP L | F13: 1841479 | G13: 43016 | H13: 120 | I13: =2+12+12+12+12 -> 50 | J13: =((F13*0.9)/H13)*I13 -> 690554.62 | K13: Land Improvement
A14: =A13+1 -> 5 | B14: General Fund | C14: 273 | D14: CIP-Other Public Infrastructures | E14: Construction of Perimeter Fence at PAnabo City Eternal Garden, Brgy. Datu Abdul, Panabo City/Project | F14: 1417023.7 | G14: 43067 | H14: 120 | I14: =1+12+12+12+12 -> 49 | J14: =((F14*0.9)/H14)*I14 -> 520756.22 | K14: Land Improvement
A15: =A14+1 -> 6 | B15: General Fund | C15: 264 | D15: CIP-Agency Assets | E15: POW#2021-05-004_Site Development for Resettlement Areas @Brgy. San Fracisco | F15: 372713.93 | G15: 44469 | H15: 120 | I15: 3 | J15: =((F15*0.9)/H15)*I15 -> 8386.0634 | K15: Land Improvement
D16: Sub-total | F16: =SUM(F11:F15) -> 4144638.9 | J16: =SUM(J11:J15) -> 1377031.7
A18: 7 | B18: General Fund | C18: 264 | D18: CIP-Agency Assets | E18: POW#2020-07-265_Rehabilitation/ Improvement of Multi-Purpose Building- Salvacion | F18: 15442.77 | G18: 44321 | H18: 60 | I18: 7 | J18: =((F18*0.9)/H18)*I18 -> 1621.4908 | K18: Other Public Infrastructure
A19: =A18+1 -> 8 | B19: General Fund | C19: 264 | D19: CIP-Agency Assets | E19: POW#2019-09-344_CONSTRUCTION OF BATCHING FOUNDATION | F19: 711475.4 | G19: 44545 | H19: 60 | I19: 0 | J19: =((F19*0.9)/H19)*I19 -> 0 | K19: Other Public Infrastructure
A20: =A19+1 -> 9 | B20: General Fund | C20: 264 | D20: CIP-Agency Assets | E20: POW#2020-07-265_Rehabilitation/ Improvement of Multi-Purpose Building- Salvacion | F20: 93654.01 | G20: 44321 | H20: 60 | I20: 7 | J20: =((F20*0.9)/H20)*I20 -> 9833.6711 | K20: Other Public Infrastructure
A21: =A20+1 -> 10 | B21: General Fund | C21: 264 | D21: CIP-Agency Assets | E21: POW#2019-12-484_COMPLETION/OPERATION OF ASPHALT BATCHING PLANT | F21: 2116700 | G21: 44418 | H21: 60 | I21: 4 | J21: =((F21*0.9)/H21)*I21 -> 127002 | K21: Other Public Infrastructure
A22: =A21+1 -> 11 | B22: General Fund | C22: 264 | D22: CIP-Agency Assets | E22: POW#2019-05-195_RENOVATION OF PANABO CITY TEEN CENTER | F22: 614913.86 | G22: 43780 | H22: 60 | I22: =1+12+12 -> 25 | J22: =((F22*0.9)/H22)*I22 -> 230592.7 | K22: Other Public Infrastructure
A23: =A22+1 -> 12 | B23: General Fund | C23: 273 | D23: CIP-Other Public Infrastructures | E23: COMPLETION OF MULTI-PURPOSE GYM, PUROK RAMIHAN, BRGY. DATU ABDUL_POW#2015-06-348 | F23: 1228689.4 | G23: 42641 | H23: 60 | I23: 60 | J23: =((F23*0.9)/H23)*I23 -> 1105820.5 | K23: Other Public Infrastructure
A24: =A23+1 -> 13 | B24: General Fund | C24: 273 | D24: CIP-Other Public Infrastructures | E24: CONSTRUCTION OF PANABO CITY MARICULTURE COMPLEX (BAYWALK PHASE III)_POW#2016-09-466 | F24: 3809282 | G24: 43134 | H24: 60 | I24: =10+12+12+12 -> 46 | J24: =((F24*0.9)/H24)*I24 -> 2628404.6 | K24: Other Public Infrastructure
A25: =A24+1 -> 14 | B25: General Fund | C25: 273 | D25: CIP-Other Public Infrastructures | E25: CONSTRUCTION OF REHABILITATION CENTER FOR CICL_POW # 2015-05-280 | F25: 1000000 | G25: 42431 | H25: 60 | I25: 60 | J25: =((F25*0.9)/H25)*I25 -> 900000 | K25: Other Public Infrastructure
A26: =A25+1 -> 15 | B26: General Fund | C26: 273 | D26: CIP-Other Public Infrastructures | E26: CONSTRUCTION OF WOMEN'S CRISIS CENTER @ BRGY. DATU ABDUL_POW # 2015-06-306 | F26: 593179.45 | G26: 42431 | H26: 60 | I26: 60 | J26: =((F26*0.9)/H26)*I26 -> 533861.51 | K26: Other Public Infrastructure
A27: =A26+1 -> 16 | B27: General Fund | C27: 273 | D27: CIP-Other Public Infrastructures | E27: CONSTRUCTION OF SOLAR DRYER, BRGY. MABUNAO_POW#2016-02-130 | F27: 328407 | G27: 42660 | H27: 60 | I27: 60 | J27: =((F27*0.9)/H27)*I27 -> 295566.3 | K27: Other Public Infrastructure
A28: =A27+1 -> 17 | B28: General Fund | C28: 273 | D28: CIP-Other Public Infrastructures | E28: CONSTRUCTION OF BAYWALK (EXPANSION ON-WARD THE SEASHORE)_POW#2017-05-454 | F28: 3593904.8 | G28: 43223 | H28: 60 | I28: =7+12+12+12 -> 43 | J28: =((F28*0.9)/H28)*I28 -> 2318068.6 | K28: Other Public Infrastructure
A29: =A28+1 -> 18 | B29: General Fund | C29: 273 | D29: CIP-Other Public Infrastructures | E29: Installation of Traffic Lights w/ Controls & Vehicle Sensor at Junction Quirino St. National Highway | F29: 3695633.9 | G29: 42923 | H29: 60 | I29: =5+12+12+12+12 -> 53 | J29: =((F29*0.9)/H29)*I29 -> 2938028.9 | K29: Other Public Infrastructure
A30: =A29+1 -> 19 | B30: General Fund | C30: 273 | D30: CIP-Other Public Infrastructures | E30: Construction of Tennis Court - Brgy. J.P Laurel, Panabo City | F30: 1445157.2 | G30: 43049 | H30: 60 | I30: =1+12+12+12+12 -> 49 | J30: =((F30*0.9)/H30)*I30 -> 1062190.5 | K30: Other Public Infrastructure
A31: =A30+1 -> 20 | B31: General Fund | C31: 273 | D31: CIP-Other Public Infrastructures | E31: CONSTRUCTION OF CONCRETE DRAINAGE, BRGY. UPPER LICANAN_POW#2015-10-587 | F31: 117900 | G31: 42653 | H31: 60 | I31: 60 | J31: =((F31*0.9)/H31)*I31 -> 106110 | K31: Other Public Infrastructure
A32: =A31+1 -> 21 | B32: General Fund | C32: 264 | D32: CIP-Agency Assets | E32: POW#2021-03-118_Construction of Water & Sanitation Facilities(2 seater w/ PWD and sink), Consolacion | F32: 29927.28 | G32: 44431 | H32: 60 | I32: 4 | J32: =((F32*0.9)/H32)*I32 -> 1795.6368 | K32: Other Public Infrastructure
D33: Sub-total | F33: =SUM(F18:F32) -> 19394267 | J33: =SUM(J18:J32) -> 12258896
A35: 22 | B35: General Fund | C35: 264 | D35: CIP-Agency Assets | E35: Renovation of Angel Barachael Drop-in Center Phase II @ Brgy. New Pandan_POW#2016-08-397 | F35: 354011.86 | G35: 42737 | H35: 60 | I35: =11+12+12+12+12 -> 59 | J35: =((F35*0.9)/H35)*I35 -> 313300.5 | K35: Other Structure
D36: Sub-total | F36: =SUM(F35) -> 354011.86 | J36: =SUM(J35) -> 313300.5
A38: 23 | B38: General Fund | C38: 267 | D38: Construction in Progress - Parks, Plazas and Monuments | E38: Improvement of Parks & Plaza: Fencing & Lightings_Old City Hall_POW#2015-04-238 | F38: 39085.07 | G38: 42535 | H38: 240 | I38: 60 | J38: =((F38*0.9)/H38)*I38 -> 8794.1408 | K38: Parks, Plazas and Monuments
A39: 24 | B39: General Fund | C39: 267 | D39: Construction in Progress - Parks, Plazas and Monuments | E39: POW#2019-12-468_Improvement of Parks and Plaza at Old City Hall- New Pandan | F39: 789737.05 | G39: 44032 | H39: 240 | I39: =5+12 -> 17 | J39: =((F39*0.9)/H39)*I39 -> 50345.737 | K39: Parks, Plazas and Monuments
D40: Sub-total | F40: =SUM(F38:F39) -> 828822.12 | J40: =SUM(J38:J39) -> 59139.878
A42: 25 | B42: General Fund | C42: 266 | D42: CIP-Roads, Highways and bridges | E42: POW#2021-05-162_Concreting of Road- Consolacion to Malativas_300mm thick x 6.70m width x 944.50 ln.m | F42: 19975730 | G42: 44477 | H42: 240 | I42: 2 | J42: =((F42*0.9)/H42)*I42 -> 149817.98 | K42: Roads, Highways and bridges
D43: Sub-total | F43: =SUM(F42:F42) -> 19975730 | J43: =SUM(J42:J42) -> 149817.98
A45: 26 | B45: General Fund | C45: 272 | D45: CIP-Waterways, Aqueducts,Seawalls, Riverwalls and Others | E45: POW#2018-12-489_CONSTRUCTION OF DRAINAGE WITHIN PANABO PUBLIC PARK | F45: 1999371.7 | G45: 43726 | H45: 240 | I45: =3+12+12 -> 27 | J45: =((F45*0.9)/H45)*I45 -> 202436.39 | K45: Waterways, Aqueducts,Seawalls, Riverwalls and Others
D46: Sub-total | F46: =SUM(F45) -> 1999371.7 | J46: =SUM(J45) -> 202436.39
D48: Total - GF | F48: =F9+F16+F33+F36+F40+F43+F46 -> 48150152 | J48: =J9+J16+J33+J36+J40+J43+J46 -> 14415122
A51: 27 | B51: SEF | C51: 269 | D51: CIP-Artesian Wells, Reservoirs, Pumping Stations and Conduits | E51: POW#2019-04-191_INSTALLATION OF WATER RESERVOIR/ TANK (BEST TANK, TAGPORE, ES | F51: 175323.86 | G51: 43754 | H51: 240 | I51: =2+12+12 -> 26 | J51: =((F51*0.9)/H51)*I51 -> 17094.076 | K51: Artesian Wells, Reservoirs, Pumping Stations and Conduits
D52: Sub-total | F52: =SUM(F51) -> 175323.86 | J52: =SUM(J51) -> 17094.076
...

Sheet J
A1: City Government of Panabo | K1: Annex J
A2: As at December 31, 2021
A4: Schedule of Completed Projects under CIP accounts
A7: No. | B7: Fund | C7: Account Code | D7: Account Title | E7: Description | F7: Amount | G7: Date Completed | H7: Estimated useful life (in months) | I7: No. of months of depreciation as at year-end | J7: Total depreciation | K7: Asset Account
A8: 1 | B8: General Fund | C8: 269 | D8: CIP-Artesian Wells, Reservoirs, Pumping Stations and Conduits | E8: POW#2019-05-204_INSTALLATION OF WATER SYSTEM WITH RAINWATER HARVESTING FACILITY AT PANABO CITY | F8: 1453309.8 | G8: 44245 | H8: 240 | I8: 10 | J8: 54499.12 | K8: Artesian Wells, Reservoirs, Pumping Stations and Conduits
D9: Sub-total | F9: =SUM(F8) -> 1453309.8 | J9: =SUM(J8) -> 54499.12
A11: 2 | B11: General Fund | C11: 264 | D11: CIP-Agency Assets | E11: POW#2019-10-001_Site Developmentfor Resettlement Areas - Land Development (DAVIN) @ Brgy. San Franci | F11: 347288.06 | G11: 44469 | H11: 120 | I11: 3 | J11: 7813.98 | K11: Land Improvement
A12: =A11+1 -> 3 | B12: General Fund | C12: 264 | D12: CIP-Agency Assets | E12: POW#2019-10-001_Site Developmentfor Resettlement Areas - Land Development (DAVIN) @ Brgy. San Franci | F12: 166134.19 | G12: 40816 | H12: 120 | I12: 120 | J12: 149520.77 | K12: Land Improvement
A13: =A12+1 -> 4 | B13: General Fund | C13: 264 | D13: CIP-Agency Assets | E13: Cons. of 477 li.m. Perimeter Fence Fronting Cityhall Government Center w/Gate Component @ Brgy. JP L | F13: 1841479 | G13: 43016 | H13: 120 | I13: =2+12+12+12+12 -> 50 | J13: 690554.63 | K13: Land Improvement
A14: =A13+1 -> 5 | B14: General Fund | C14: 273 | D14: CIP-Other Public Infrastructures | E14: Construction of Perimeter Fence at PAnabo City Eternal Garden, Brgy. Datu Abdul, Panabo City/Project | F14: 1417023.7 | G14: 43067 | H14: 120 | I14: =1+12+12+12+12 -> 49 | J14: 520756.22 | K14: Land Improvement
A15: =A14+1 -> 6 | B15: General Fund | C15: 264 | D15: CIP-Agency Assets | E15: POW#2021-05-004_Site Development for Resettlement Areas @Brgy. San Fracisco | F15: 372713.93 | G15: 44469 | H15: 120 | I15: 3 | J15: 8386.06 | K15: Land Improvement
D16: Sub-total | F16: =SUM(F11:F15) -> 4144638.9 | J16: =SUM(J11:J15) -> 1377031.7
A18: 7 | B18: General Fund | C18: 264 | D18: CIP-Agency Assets | E18: POW#2020-07-265_Rehabilitation/ Improvement of Multi-Purpose Building- Salvacion | F18: 15442.77 | G18: 44321 | H18: 60 | I18: 7 | J18: 1621.49 | K18: Other Public Infrastructure
A19: =A18+1 -> 8 | B19: General Fund | C19: 264 | D19: CIP-Agency Assets | E19: POW#2019-09-344_CONSTRUCTION OF BATCHING FOUNDATION | F19: 711475.4 | G19: 44545 | H19: 60 | I19: 0 | J19: 0 | K19: Other Public Infrastructure
A20: =A19+1 -> 9 | B20: General Fund | C20: 264 | D20: CIP-Agency Assets | E20: POW#2020-07-265_Rehabilitation/ Improvement of Multi-Purpose Building- Salvacion | F20: 93654.01 | G20: 44321 | H20: 60 | I20: 7 | J20: 9833.67 | K20: Other Public Infrastructure
A21: =A20+1 -> 10 | B21: General Fund | C21: 264 | D21: CIP-Agency Assets | E21: POW#2019-12-484_COMPLETION/OPERATION OF ASPHALT BATCHING PLANT | F21: 2116700 | G21: 44418 | H21: 60 | I21: 4 | J21: 127002 | K21: Other Public Infrastructure
A22: =A21+1 -> 11 | B22: General Fund | C22: 264 | D22: CIP-Agency Assets | E22: POW#2019-05-195_RENOVATION OF PANABO CITY TEEN CENTER | F22: 614913.86 | G22: 43780 | H22: 60 | I22: =1+12+12 -> 25 | J22: 230592.7 | K22: Other Public Infrastructure
A23: =A22+1 -> 12 | B23: General Fund | C23: 273 | D23: CIP-Other Public Infrastructures | E23: COMPLETION OF MULTI-PURPOSE GYM, PUROK RAMIHAN, BRGY. DATU ABDUL_POW#2015-06-348 | F23: 1228689.4 | G23: 42641 | H23: 60 | I23: 60 | J23: 1105820.5 | K23: Other Public Infrastructure
A24: =A23+1 -> 13 | B24: General Fund | C24: 273 | D24: CIP-Other Public Infrastructures | E24: CONSTRUCTION OF PANABO CITY MARICULTURE COMPLEX (BAYWALK PHASE III)_POW#2016-09-466 | F24: 3809282 | G24: 43134 | H24: 60 | I24: =10+12+12+12 -> 46 | J24: 2628404.6 | K24: Other Public Infrastructure
A25: =A24+1 -> 14 | B25: General Fund | C25: 273 | D25: CIP-Other Public Infrastructures | E25: CONSTRUCTION OF REHABILITATION CENTER FOR CICL_POW # 2015-05-280 | F25: 1000000 | G25: 42431 | H25: 60 | I25: 60 | J25: 900000 | K25: Other Public Infrastructure
A26: =A25+1 -> 15 | B26: General Fund | C26: 273 | D26: CIP-Other Public Infrastructures | E26: CONSTRUCTION OF WOMEN'S CRISIS CENTER @ BRGY. DATU ABDUL_POW # 2015-06-306 | F26: 593179.45 | G26: 42431 | H26: 60 | I26: 60 | J26: 533861.51 | K26: Other Public Infrastructure
A27: =A26+1 -> 16 | B27: General Fund | C27: 273 | D27: CIP-Other Public Infrastructures | E27: CONSTRUCTION OF SOLAR DRYER, BRGY. MABUNAO_POW#2016-02-130 | F27: 328407 | G27: 42660 | H27: 60 | I27: 60 | J27: 295566.3 | K27: Other Public Infrastructure
A28: =A27+1 -> 17 | B28: General Fund | C28: 273 | D28: CIP-Other Public Infrastructures | E28: CONSTRUCTION OF BAYWALK (EXPANSION ON-WARD THE SEASHORE)_POW#2017-05-454 | F28: 3593904.8 | G28: 43223 | H28: 60 | I28: =7+12+12+12 -> 43 | J28: 2318068.6 | K28: Other Public Infrastructure
A29: =A28+1 -> 18 | B29: General Fund | C29: 273 | D29: CIP-Other Public Infrastructures | E29: Installation of Traffic Lights w/ Controls & Vehicle Sensor at Junction Quirino St. National Highway | F29: 3695633.9 | G29: 42923 | H29: 60 | I29: =5+12+12+12+12 -> 53 | J29: 2938028.9 | K29: Other Public Infrastructure
A30: =A29+1 -> 19 | B30: General Fund | C30: 273 | D30: CIP-Other Public Infrastructures | E30: Construction of Tennis Court - Brgy. J.P Laurel, Panabo City | F30: 1445157.2 | G30: 43049 | H30: 60 | I30: =1+12+12+12+12 -> 49 | J30: 1062190.5 | K30: Other Public Infrastructure
A31: =A30+1 -> 20 | B31: General Fund | C31: 273 | D31: CIP-Other Public Infrastructures | E31: CONSTRUCTION OF CONCRETE DRAINAGE, BRGY. UPPER LICANAN_POW#2015-10-587 | F31: 117900 | G31: 42653 | H31: 60 | I31: 60 | J31: 106110 | K31: Other Public Infrastructure
A32: =A31+1 -> 21 | B32: General Fund | C32: 264 | D32: CIP-Agency Assets | E32: POW#2021-03-118_Construction of Water & Sanitation Facilities(2 seater w/ PWD and sink), Consolacion | F32: 29927.28 | G32: 44431 | H32: 60 | I32: 4 | J32: 1795.64 | K32: Other Public Infrastructure
D33: Sub-total | F33: =SUM(F18:F32) -> 19394267 | J33: =SUM(J18:J32) -> 12258896
A35: 22 | B35: General Fund | C35: 264 | D35: CIP-Agency Assets | E35: Renovation of Angel Barachael Drop-in Center Phase II @ Brgy. New Pandan_POW#2016-08-397 | F35: 354011.86 | G35: 42737 | H35: 60 | I35: =11+12+12+12+12 -> 59 | J35: 313300.5 | K35: Other Structure
D36: Sub-total | F36: =SUM(F35) -> 354011.86 | J36: =SUM(J35) -> 313300.5
A38: 23 | B38: General Fund | C38: 267 | D38: Construction in Progress - Parks, Plazas and Monuments | E38: Improvement of Parks & Plaza: Fencing & Lightings_Old City Hall_POW#2015-04-238 | F38: 39085.07 | G38: 42535 | H38: 240 | I38: 60 | J38: 8794.14 | K38: Parks, Plazas and Monuments
A39: 24 | B39: General Fund | C39: 267 | D39: Construction in Progress - Parks, Plazas and Monuments | E39: POW#2019-12-468_Improvement of Parks and Plaza at Old City Hall- New Pandan | F39: 789737.05 | G39: 44032 | H39: 240 | I39: =5+12 -> 17 | J39: 50345.74 | K39: Parks, Plazas and Monuments
D40: Sub-total | F40: =SUM(F38:F39) -> 828822.12 | J40: =SUM(J38:J39) -> 59139.88
A42: 25 | B42: General Fund | C42: 266 | D42: CIP-Roads, Highways and bridges | E42: POW#2021-05-162_Concreting of Road- Consolacion to Malativas_300mm thick x 6.70m width x 944.50 ln.m | F42: 19975730 | G42: 44477 | H42: 240 | I42: 2 | J42: 149817.98 | K42: Roads, Highways and bridges
D43: Sub-total | F43: =SUM(F42:F42) -> 19975730 | J43: =SUM(J42:J42) -> 149817.98
A45: 26 | B45: General Fund | C45: 272 | D45: CIP-Waterways, Aqueducts,Seawalls, Riverwalls and Others | E45: POW#2018-12-489_CONSTRUCTION OF DRAINAGE WITHIN PANABO PUBLIC PARK | F45: 1999371.7 | G45: 43726 | H45: 240 | I45: =3+12+12 -> 27 | J45: 202436.39 | K45: Waterways, Aqueducts,Seawalls, Riverwalls and Others
D46: Sub-total | F46: =SUM(F45) -> 1999371.7 | J46: =SUM(J45) -> 202436.39
D48: Total - GF | F48: =F9+F16+F33+F36+F40+F43+F46 -> 48150152 | J48: =J9+J16+J33+J36+J40+J43+J46 -> 14415122
A51: 27 | B51: SEF | C51: 269 | D51: CIP-Artesian Wells, Reservoirs, Pumping Stations and Conduits | E51: POW#2019-04-191_INSTALLATION OF WATER RESERVOIR/ TANK (BEST TANK, TAGPORE, ES | F51: 175323.86 | G51: 43754 | H51: 240 | I51: =2+12+12 -> 26 | J51: 17094.08 | K51: Artesian Wells, Reservoirs, Pumping Stations and Conduits
D52: Sub-total | F52: =SUM(F51) -> 175323.86 | J52: =SUM(J51) -> 17094.08
...

Sheet K
A1: City Government of Panabo | D1: Annex K
A2: As at December 31, 2021
A4: List of beneficiaries at Barangay Quezon
A7: No. | B7: Name | C7: Status | D7: Year Hired
A8: 1 | B8: Acdal, Wilfredo M | C8: permanent | D8: 2010
A9: 2 | B9: Acosta, Lenita B | C9: retired | D9: 1993
A10: 3 | B10: Aguisando, Helene May S | C10: permanent | D10: 2000
A11: 4 | B11: Albasin, Randy A | C11: permanent | D11: 2001
A12: 5 | B12: Almorato, Rex Joy C | C12: permanent | D12: 1993
A13: 6 | B13: Alpuerto, Amy B | C13: permanent | D13: 2000
A14: 7 | B14: Amper, Salee C | C14: permanent | D14: 2002
A15: 8 | B15: Atanoza, Novie Joy M | C15: permanent | D15: 2007
A16: 9 | B16: Bacalso, Perla B | C16: permanent | D16: 1991
A17: 10 | B17: Balaga, Myrna M | C17: permanent | D17: 2007
A18: 11 | B18: Balagot, Edito G | C18: retired | D18: 1999
A19: 12 | B19: Balanay, Erchied J | C19: permanent | D19: 1996
... A126: 119 | B126: Fe Garcia | C126: permanent | D126: 2011

Sheet L
A1: City Government of Panabo | D1: Annex L
A2: As at December 31, 2021
A4: List of beneficiaries who owned a lot
A6: No. | B6: Name
A7: 1 | B7: Acosta, Lenita B | C7: retired
A8: =A7+1 -> 2 | B8: Albasin, Randy A | C8: permanent
A9: =A8+1 -> 3 | B9: Amper, Salee C | C9: permanent
A10: =A9+1 -> 4 | B10: Bacalso, Perla B | C10: permanent
A11: =A10+1 -> 5 | B11: Balaga, Myrna M | C11: permanent
A12: =A11+1 -> 6 | B12: Benedicto, Juliet S | C12: permanent
A13: =A12+1 -> 7 | B13: Bernaldez, Gloria T | C13: retired
A14: =A13+1 -> 8 | B14: Cozo, Crsitito D | C14: permanent
A15: =A14+1 -> 9 | B15: Dela Gente, Jackie Joseph F | C15: permanent
A16: =A15+1 -> 10 | B16: Dela gente, Juliet C | C16: permanent
A17: =A16+1 -> 11 | B17: Deloso, Annabelle A | C17: permanent
A18: =A17+1 -> 12 | B18: Descuatan, Elinita A | C18: permanent
A19: =A18+1 -> 13 | B19: Dianzon, Daisy L | C19: permanent
... A44: =A43+1 -> 38 | B44: Fe Garcia | C44: permanent

Sheet M
C1: Annex M
C2: CY 2021 Financial Reports of Panabo City as posted in FDP Portal
B4: Annual Budget Report; | C4: Annual Budget Report:
B5: Annual Procurement Plan;
B6: Statement of Receipts and Expenditures;
B7: GAD Accomplishment Report;
B8: Local Disaster Risk and Reduction and Management Fund Utilization;
B9: Special Education Fund Utilization
B10: 20% Component of the IRA Utilization;
B13: Trust Fund Utilization | C13: Annual Procurement Plan:
B14: Quarterly Statement of Cash Flows;
B15: Supplemental Procurement Plan; and
B16: Manpower Component
C21: Supplemental Procurement Plan:
C30: Statement of Receipts and Expenditures:
C38: GAD Accomplishment Report:
