Workbook

Sheet SFPO
A1: City Government of Panabo
A2: Province of Davao del Norte
A3: STATEMENT OF FINANCIAL POSITION
A4: All Funds
A5: As at December 31, 2022
A6: (With Comparative Figures for CY 2021)
A7: (In Philippine Peso)
B9: Note | D9: 2022 | F9: 2021
A10: ASSETS
A11: Current Assets
A12: Cash and Cash Equivalents | B12: 4 | D12: 1.5002771e+09 | F12: 1.3550813e+09 | H12: =D12-#REF! -> #REF! | I12: =F12-#REF! -> #REF!
A13: Investments | B13: 5 | D13: 35790297 | F13: 27751603 | H13: =D13-#REF! -> #REF! | I13: =F13-#REF! -> #REF!
A14: Receivables | B14: 6 | D14: 2.7125557e+08 | F14: 1.8293766e+08 | H14: =D14-#REF! -> #REF! | I14: =F14-#REF! -> #REF!
A15: Inventories | B15: 7 | D15: 1.6258755e+08 | F15: 1.4565748e+08 | H15: =D15-#REF! -> #REF! | I15: =F15-#REF! -> #REF!
A16: Prepayments and Deferred Charges | B16: 8 | D16: 82238189 | F16: 15970831 | H16: =D16-#REF! -> #REF! | I16: =F16-#REF! -> #REF!
A17: Total Current Assets | D17: =SUM(D12:D16) -> 2.0521487e+09 | F17: =SUM(F12:F16) -> 1.7273988e+09 | H17: =D17-#REF! -> #REF! | I17: =F17-#REF! -> #REF!
A19: Non-Current Assets
A20: Property, Plant and Equipment (net) | B20: 10 | D20: =21468681.54+3103181840.55 -> 3.1246505e+09 | F20: 2.4551166e+09 | H20: =D20-#REF! -> #REF! | I20: =F20-#REF! -> #REF!
A21: Biological Assets | D21: 0 | F21: 124150 | H21: =D21-#REF! -> #REF! | I21: =F21-#REF! -> #REF!
A22: Intangible Assets | B22: 10 | D22: 42783.33 | F22: 430673.03 | H22: =D22-#REF! -> #REF! | I22: =F22-#REF! -> #REF!
A23: Total Non-Current Assets | D23: =SUM(D20:D22) -> 3.1246933e+09 | F23: =SUM(F20:F22) -> 2.4556715e+09 | H23: =D23-#REF! -> #REF! | I23: =F23-#REF! -> #REF!
A24: Total Assets | D24: =D23+D17 -> 5.176842e+09 | F24: =F23+F17 -> 4.1830703e+09 | H24: =D24-#REF! -> #REF! | I24: =F24-#REF! -> #REF!
A26: LIABILITIES
A27: Current Liabilities
A28: Financial Liabilities | B28: 11, 12 | D28: 1.989913e+08 | F28: =127235905.41+749493.83 -> 1.279854e+08 | H28: =D28-#REF! -> #REF! | I28: =F28-#REF! -> #REF!
A29: Inter-Agency Payables | B29: 13 | D29: 2.9464755e+08 | F29: 4.897553e+08 | H29: =D29-#REF! -> #REF! | I29: =F29-#REF! -> #REF!
A30: Intra-Agency Payables | B30: 14 | D30: 43743842 | F30: 80916349 | H30: =D30-#REF! -> #REF! | I30: =F30-#REF! -> #REF!
A31: Trust Liabilities | B31: 15 | D31: 1.7514942e+08 | F31: 1.1420422e+08 | H31: =D31-#REF! -> #REF! | I31: =F31-#REF! -> #REF!
A32: Provisions | D32: 0 | F32: 528146.84 | H32: =D32-#REF! -> #REF! | I32: =F32-#REF! -> #REF!
A33: Deferred Credits/Unearned Income | B33: 16 | D33: 2.6539762e+08 | F33: 19610913 | H33: =D33-#REF! -> #REF! | I33: =F33-#REF! -> #REF!
A34: Other Payables | B34: 17 | D34: 26964251 | F34: 73845619 | H34: =D34-#REF! -> #REF! | I34: =F34-#REF! -> #REF!
A35: Total Current Liabilities | D35: =SUM(D28:D34) -> 1.004894e+09 | F35: =SUM(F28:F34) -> 9.0684594e+08 | H35: =D35-#REF! -> #REF!
A37: Non-Current Liabilities
A38: Financial Liabilities | B38: 12 | D38: 5.8605084e+08 | F38: 2.4759494e+08 | H38: =D38-#REF! -> #REF! | I38: =F38-#REF! -> #REF!
A39: Deferred Credits/Unearned Income | D39: 15168796 | F39: 1572986 | H39: =D39-#REF! -> #REF! | I39: =F39-#REF! -> #REF!
A40: Total Non-Current Liabilities | D40: =SUM(D38:D39) -> 6.0121964e+08 | F40: =SUM(F38:F39) -> 2.4916793e+08 | H40: =D40-#REF! -> #REF! | I40: =F40-#REF! -> #REF!
A41: Total Liabilities | D41: =D35+D40 -> 1.6061136e+09 | F41: =F35+F40 -> 1.1560139e+09 | H41: =D41-#REF! -> #REF! | I41: =F41-#REF! -> #REF!
A43: NET ASSETS/EQUITY
A44: Government Equity | B44: 29 | D44: =SCNAE!D19 -> 3.5707283e+09 | F44: 3.0270564e+09 | H44: =D44-#REF! -> #REF! | I44: =F44-#REF! -> #REF!
A45: Total Liabilities and Net Assets/Equity | D45: =D44+D41 -> 5.176842e+09 | F45: =F44+F41 -> 4.1830703e+09 | H45: =D45-#REF! -> #REF! | I45: =F45-#REF! -> #REF!
...

Sheet SFPER
A1: City Government of Panabo
A2: Province of Davao del Norte
A3: STATEMENT OF FINANCIAL PERFORMANCE
A4: All Funds
A5: For the Year Ended December 31, 2022
A6: (With Comparative Figures for CY 2021)
A7: (In Philippine Peso)
B9: Note/s | D9: 2022 | F9: 2021
A10: Revenue
A11: Tax Revenue | B11: 18 | D11: 3.1547791e+08 | F11: 2.9471068e+08 | G11: =D11-#REF! -> #REF! | I11: =F11-#REF! -> #REF!
A12: Share from Internal Revenue Collections | B12: 18 | D12: 1248221550 | F12: 889216030 | G12: =D12-#REF! -> #REF! | I12: =F12-#REF! -> #REF!
A13: Other Shares from National Taxes | D13: 0 | F13: 72609 | G13: =D13-#REF! -> #REF! | I13: =F13-#REF! -> #REF!
A14: Service and Business Income | B14: 19 | D14: 1.6759424e+08 | F14: 1.4346942e+08 | G14: =D14-#REF! -> #REF! | I14: =F14-#REF! -> #REF!
A15: Shares, Grants and Donations | B15: 21 | D15: 84539859 | F15: 4548753.6 | G15: =D15-#REF! -> #REF! | I15: =F15-#REF! -> #REF!
A16: Total Revenue | D16: =SUM(D11:D15) -> 1.8158336e+09 | F16: =SUM(F11:F15) -> 1.3320175e+09
A18: Less: Current Operating Expenses
A19: Personnel Services | B19: 23 | D19: 4.644253e+08 | F19: 3.8409563e+08 | G19: =D19-#REF! -> #REF! | I19: =F19-#REF! -> #REF!
A20: Maintenance & Other Operating Expenses | B20: 24, 22 | D20: =527078077.37+2647.87 -> 5.2708073e+08 | F20: 4.923733e+08 | G20: =D20-#REF! -> #REF! | I20: =F20-#REF! -> #REF!
A21: Non-cash Expenses | B21: 27 | D21: 1.239231e+08 | F21: 1.2077748e+08 | G21: =D21-#REF! -> #REF! | I21: =F21-#REF! -> #REF!
A22: Financial Expenses | B22: 25 | D22: 21498605 | F22: 10687840 | G22: =D22-#REF! -> #REF! | I22: =F22-#REF! -> #REF!
A23: Current Operating Expenses | D23: =SUM(D19:D22) -> 1.1369277e+09 | F23: =SUM(F19:F22) -> 1.0079343e+09 | G23: =D23-#REF! -> #REF! | I23: =F23-#REF! -> #REF!
A25: Surplus (Deficit) from Current Operation | D25: =D16-D23 -> 6.7890584e+08 | F25: =F16-F23 -> 3.2408323e+08 | G25: =D25-#REF! -> #REF! | I25: =F25-#REF! -> #REF!
A26: Add (Deduct):
A27: Transfers, Assistance and Subsidy From | B27: 20 | D27: 10612958 | F27: 1.5304759e+08 | G27: =D27-#REF! -> #REF! | I27: =F27-#REF! -> #REF!
A28: Transfers, Assistance and Subsidy To | B28: 24 | D28: -21104847 | F28: -55694875 | G28: =D28-#REF! -> #REF! | I28: =F28+#REF! -> #REF!
A29: Miscellaneous Income | B29: 22 | D29: 2218956.3 | F29: 1643931.5 | G29: =D29-#REF! -> #REF! | I29: =F29-#REF! -> #REF!
A30: Surplus(Deficit) for the period | D30: =SUM(D25:D29) -> 6.706329e+08 | F30: =SUM(F25:F29) -> 4.2307988e+08 | G30: =D30-#REF! -> #REF! | I30: =F30-#REF! -> #REF!
A32: (See accompanying Notes to Financial Statements.)

Sheet SCNAE
A1: City Government of Panabo
A2: Province of Davao del Norte
A3: STATEMENT OF CHANGES IN NET ASSETS/EQUITY
A4: All Funds
A5: For the Year Ended December 31, 2022
A6: (With Comparative Figures for CY 2021)
A7: (In Philippine Peso)
B9: Note/s | D9: 2022 | F9: 2021
A10: Balance at January 1 | D10: =F19 -> 3.0270564e+09 | F10: 2.9496322e+09 | H10: =D10-#REF! -> #REF! | I10: =F10-#REF! -> #REF!
A11: Add (Deduct):
A12: Changes in Accounting Policy | D12: 0 | F12: 0 | I12: =F12-#REF! -> #REF!
A13: Prior Period Errors | B13: 28 | D13: -1.2696097e+08 | F13: -3.4565567e+08 | H13: =D13-#REF! -> #REF! | I13: =F13-#REF! -> #REF!
A14: Restated Balance | D14: =SUM(D10:D13) -> 2.9000954e+09 | F14: =F10+F12+F13 -> 2.6039765e+09 | H14: =D14-#REF! -> #REF! | I14: =F14-#REF! -> #REF!
A15: Add (Deduct):
A16: Changes in net assets/equity during the year | D16: 0 | F16: 0
A17: Surplus (Deficit) for the period | D17: =SFPER!D30 -> 6.706329e+08 | F17: =SFPER!F30 -> 4.2307988e+08 | H17: =D17-#REF! -> #REF! | I17: =F17-#REF! -> #REF!
A18: Total changes during the year | D18: =D17 -> 6.706329e+08 | F18: =F17 -> 4.2307988e+08
A19: Balance at December 31, 2022 | D19: =D14+D18 -> 3.5707283e+09 | F19: =F14+F17 -> 3.0270564e+09
A21: (See accompanying Notes to Financial Statements.)

Sheet SCF
A1: City Government of Panabo
A2: Province of Davao del Norte
A3: STATEMENT OF CASH FLOWS
A4: All Funds
A5: For the Year Ended December 31, 2022
A6: (With Comparative Figures for CY 2021)
A7: (In Philippine Peso)
B9: Note/s | D9: 2022 | F9: 2021
A10: Cash Flows from Operating Activities
A11: Cash Inflows
A12: Collection from taxpayers | D12: 3.9815268e+08 | F12: 2.9727308e+08
A13: Share from Internal Revenue Allotment | D13: 1248221550 | F13: 889216030
A14: Receipts from business/service income | D14: 63908116 | F14: 1.0571275e+08
A15: Interest Income | D15: 723892.42 | F15: 385197.82
A16: Other Receipts | D16: 4.3425308e+08 | F16: 1.2310862e+09
A17: Total Cash Inflows | D17: =+SUM(D12:D16) -> 2.1452593e+09 | F17: =+SUM(F12:F16) -> 2.5236732e+09
A18: Cash Outflows
A19: Payment of expenses | D19: 2.9027632e+08 | F19: 3.3530866e+08
A20: Payments to suppliers and creditors | D20: 1.070058e+08 | F20: 1.8193685e+08
A21: Payments to employees | D21: 5.3077991e+08 | F21: 2.581936e+08
A22: Interest Expense | D22: 20139328 | F22: 10419963
A23: Other Expenses | D23: 9.5945754e+08 | F23: 9.816656e+08
A24: Total Cash Outflows | D24: =+SUM(D19:D23) -> 1.9076589e+09 | F24: =+SUM(F19:F23) -> 1.7675247e+09
A25: Net Cash Flows from Operating Activities | D25: =D17-D24 -> 2.3760043e+08 | F25: =F17-F24 -> 7.5614854e+08
A27: Cash Flow from Investing Activities
A28: Cash Inflows
A29: Proceeds from Sale/Disposal of PPE | D29: 11519.46 | F29: 0
A30: Total Cash Inflows | D30: =+D29 -> 11519.46 | F30: =+F29 -> 0
A31: Cash Outflows
A32: Purchase/Construction of PPE | D32: 4.6080316e+08 | F32: 5.3812719e+08
A33: Total Cash Outflows | D33: =+D32 -> 4.6080316e+08 | F33: =+F32 -> 5.3812719e+08
A34: Net Cash Flows from Investing Activities | D34: =+D30-D33 -> -4.6079165e+08 | F34: =+F30-F33 -> -5.3812719e+08
A36: Cash Flows from Financing Activities
A37: Cash Inflows
A38: Proceeds from Domestic Loans | D38: 4.0106858e+08 | F38: 9564783
A39: Total Cash Inflows | D39: =+D38 -> 4.0106858e+08 | F39: =+F38 -> 9564783
A40: Cash Outflows
A41: Payment of Long-Term Liabilities | D41: 32681550 | F41: 26694021
A42: Total Cash Outflows | D42: =+D41 -> 32681550 | F42: =+F41 -> 26694021
A43: Net Cash Flows from Financing Activities | D43: =D39-D42 -> 3.6838703e+08 | F43: =F39-F42 -> -17129238
...

Sheet SCBAA
A1: City Government of Panabo
A2: Province of Davao del Norte
A3: STATEMENT OF COMPARISON OF BUDGET AND ACTUAL AMOUNTS
A4: For the Year Ended December 31, 2022
A5: (In Philippine Peso)
A7: PARTICULARS | F7: Note | G7: Budgeted | K7: Difference | P7: Difference
G8: Amounts | K8: Original and | N8: Actual | P8: Final Budget
H9: Original | J9: Final | K9: Final Budget | N9: Amounts | P9: and Actual
F10: 30
A11: Revenue
B12: A. Local Sources
C13: 1. Tax Revenue
D14: a. Tax Revenue - Property | H14: 105650000 | J14: 105650000 | L14: =H14-J14 -> 0 | N14: 1.1755982e+08 | P14: =J14-N14 -> -11909823
D15: b. Tax Revenue - Goods and Services | H15: 167912000 | J15: 167912000 | L15: =H15-J15 -> 0 | N15: 1.9313822e+08 | P15: =J15-N15 -> -25226220
D16: c. Other Local Taxes | L16: =H16-J16 -> 0 | N16: 10252041 | P16: =J16-N16 -> -10252041
C17: Total Tax Revenue | H17: =SUM(H14:H16) -> 273562000 | J17: =SUM(J14:J16) -> 273562000 | L17: =SUM(L14:L16) -> 0 | N17: =SUM(N14:N16) -> 3.2095008e+08 | P17: =SUM(P14:P16) -> -47388084
C18: 2. Non-Tax Revenue
D19: a. Service Income | H19: 50867175 | J19: 51462805 | L19: =H19-J19 -> -595630 | N19: 53643787 | P19: =J19-N19 -> -2180982
D20: b. Business Income | H20: 89839352 | J20: 90089352 | L20: =H20-J20 -> -250000 | N20: 86239969 | P20: =J20-N20 -> 3849383.8
D21: c. Other Income and Receipts | H21: 4.3644277e+08 | J21: 5.8674285e+08 | L21: =H21-J21 -> -1.5030008e+08 | N21: 5.8752351e+08 | P21: =J21-N21 -> -780656.54
C22: Total Non-Tax Revenue | H22: =SUM(H19:H21) -> 5.771493e+08 | J22: =SUM(J19:J21) -> 7.2829501e+08 | L22: =SUM(L19:L21) -> -1.5114571e+08 | N22: =SUM(N19:N21) -> 7.2740726e+08 | P22: =SUM(P19:P21) -> 887745.28
B23: B. External Sources
C24: 1. Share from the National Internal Revenue Taxes | H24: 889216030 | J24: 1248221550 | L24: =H24-J24 -> -359005520 | N24: 1248221550 | P24: =J24-N24 -> 0
C25: 2. Share from GOCCs
D26: a. Share from PCSO | H26: 1000000 | J26: 1000000 | L26: =H26-J26 -> 0 | N26: 1523631.2 | P26: =J26-N26 -> -523631.25
C27: 3. Other Shares from National Tax Collections
D28: a. Share from Ecozone | L28: 0 | P28: =J28-N28 -> 0
D29: b. Share from National Wealth | L29: =H29-J29 -> 0 | P29: =J29-N29 -> 0
C30: 4. Other Receipts
D31: a. Grants and Donations | L31: =H31-J31 -> 0 | P31: =J31-N31 -> 0
D32: b. Other Subsidy Income | H32: 2800000 | J32: 10612958 | L32: =H32-J32 -> -7812957.5 | N32: 10612958 | P32: =J32-N32 -> 0
C33: 5. Inter-local Transfer | L33: =H33-J33 -> 0 | P33: =J33-N33 -> 0
C34: 6. Capital /Investment Receipts
D35: a. Sale of Capital Assets | L35: =H35-J35 -> 0 | P35: =J35-N35 -> 0
D36: b. Sale of Investments | L36: =H36-J36 -> 0 | P36: =J36-N36 -> 0
D37: c. Proceeds from Collections of Loan Receivable | L37: =H37-J37 -> 0 | P37: =J37-N37 -> 0
B38: C. Receipts from Borrowings | H38: 3.9348016e+08 | J38: 3.9348016e+08 | L38: =H38-J38 -> 0 | N38: 3.9348016e+08 | P38: =J38-N38 -> 0
A39: Total Revenue and Receipts | H39: =H17+H22+H24+H26+H28+H29+H38+H33+H32 -> 2.1372075e+09 | J39: =J17+J22+J24+J26+J28+J29+J38+J33+J32 -> 2.6551717e+09 | L39: =L17+L22+L24+L26+L28+L29+L38+L33+L32 -> -5.1796418e+08 | N39: =N17+N22+N24+N26+N28+N29+N38+N33+N32 -> 2.7021956e+09 | P39: =P17+P22+P24+P26+P28+P29+P38+P33+P32 -> -47023970
A41: Expenditures
A42: Current Aprropriations
...
